Workbook

Sheet Sheet1
A1: CN | B1: Glider | C1: Pilot
A2: FL | B2: EB29R | C2: Felipe Levin
A3: YY | B3: JS5 | C3: Sebastian Kawa
A4: OR | B4: EB29R | C4: Michael Sommer
A5: 72 | B5: EB29R | C5: Sylvain Gerbaud
A6: 5 | B6: JS5 | C6: Laurent Aboulin
A7: EX | B7: EB29R | C7: Tomas Rendla
A8: IP3 | B8: EB29DR | C8: Pierre de Broqueville
A9: 1E | B9: JS5 | C9: Russell Cheetham
A10: UFO | B10: EB29DR | C10: Max Leenders
A11: ZFI | B11: JS1-21 | C11: Jiri Kusbach
A12: XR | B12: EB29R | C12: Bas Seijffert
... A16: B | B16: JS3-18 | C16: Jan Buch-Madsen

Sheet T1
A1: Glider | B1: Pilot | C1: Speed | D1: Distance | E1: Finished | F1: Speed Pt | G1: Dist Pt | H1: TOTAL PT | I1: Penalty
A2: FL | B2: Felipe Levin | C2: 120.79 | D2: 382.25 | E2: =TRUE -> TRUE | F2: =IF(E2, $B$37 * MAX(0, (C2 - 2/3*$B$23) / (1/3*$B$23)), 0) -> 666.66667 | G2: =IF(E2, $B$38, $B$38 * (D2/$B$30)) -> 333.33333 | H2: =Day_1[[#This Row],[Speed Pt]]+Day_1[[#This Row],[Dist Pt]] -> 1000 | I2: 0
A3: OR | B3: =_xlfn.XLOOKUP(Day_1[[#This Row],[Glider]],Sheet1!$A$2:$A$16,Sheet1!$C$2:$C$16) -> Michael Sommer | C3: 120.13 | D3: 383.62 | E3: =TRUE -> TRUE | F3: =IF(E3, $B$37 * MAX(0, (C3 - 2/3*$B$23) / (1/3*$B$23)), 0) -> 655.73861 | G3: =IF(E3, $B$38, $B$38 * (D3/$B$30)) -> 333.33333 | H3: =Day_1[[#This Row],[Speed Pt]]+Day_1[[#This Row],[Dist Pt]] -> 989.07194 | I3: 0
A4: XR | B4: =_xlfn.XLOOKUP(Day_1[[#This Row],[Glider]],Sheet1!$A$2:$A$16,Sheet1!$C$2:$C$16) -> Bas Seijffert | C4: 110.69 | D4: 354.72 | E4: =TRUE -> TRUE | F4: =IF(E4, $B$37 * MAX(0, (C4 - 2/3*$B$23) / (1/3*$B$23)), 0) -> 499.43428 | G4: =IF(E4, $B$38, $B$38 * (D4/$B$30)) -> 333.33333 | H4: =Day_1[[#This Row],[Speed Pt]]+Day_1[[#This Row],[Dist Pt]] -> 832.76761 | I4: 0
A5: 5 | B5: =_xlfn.XLOOKUP(Day_1[[#This Row],[Glider]],Sheet1!$A$2:$A$16,Sheet1!$C$2:$C$16) -> Laurent Aboulin | C5: 109.66 | D5: 364.54 | E5: =TRUE -> TRUE | F5: =IF(E5, $B$37 * MAX(0, (C5 - 2/3*$B$23) / (1/3*$B$23)), 0) -> 482.37989 | G5: =IF(E5, $B$38, $B$38 * (D5/$B$30)) -> 333.33333 | H5: =Day_1[[#This Row],[Speed Pt]]+Day_1[[#This Row],[Dist Pt]] -> 815.71322 | I5: 0
A6: IP3 | B6: =_xlfn.XLOOKUP(Day_1[[#This Row],[Glider]],Sheet1!$A$2:$A$16,Sheet1!$C$2:$C$16) -> Pierre de Broqueville | C6: 109.68 | D6: 334.66 | E6: =TRUE -> TRUE | F6: =IF(E6, $B$37 * MAX(0, (C6 - 2/3*$B$23) / (1/3*$B$23)), 0) -> 482.71104 | G6: =IF(E6, $B$38, $B$38 * (D6/$B$30)) -> 333.33333 | H6: =Day_1[[#This Row],[Speed Pt]]+Day_1[[#This Row],[Dist Pt]] -> 816.04437 | I6: 0
A7: 72 | B7: =_xlfn.XLOOKUP(Day_1[[#This Row],[Glider]],Sheet1!$A$2:$A$16,Sheet1!$C$2:$C$16) -> Sylvain Gerbaud | C7: 109.46 | D7: 363.98 | E7: =TRUE -> TRUE | F7: =IF(E7, $B$37 * MAX(0, (C7 - 2/3*$B$23) / (1/3*$B$23)), 0) -> 479.06836 | G7: =IF(E7, $B$38, $B$38 * (D7/$B$30)) -> 333.33333 | H7: =Day_1[[#This Row],[Speed Pt]]+Day_1[[#This Row],[Dist Pt]] -> 812.40169 | I7: 0
A8: YY | B8: =_xlfn.XLOOKUP(Day_1[[#This Row],[Glider]],Sheet1!$A$2:$A$16,Sheet1!$C$2:$C$16) -> Sebastian Kawa | C8: 104.73 | D8: 351.62 | E8: =TRUE -> TRUE | F8: =IF(E8, $B$37 * MAX(0, (C8 - 2/3*$B$23) / (1/3*$B$23)), 0) -> 400.75061 | G8: =IF(E8, $B$38, $B$38 * (D8/$B$30)) -> 333.33333 | H8: =Day_1[[#This Row],[Speed Pt]]+Day_1[[#This Row],[Dist Pt]] -> 734.08395 | I8: 0
A9: DD | B9: =_xlfn.XLOOKUP(Day_1[[#This Row],[Glider]],Sheet1!$A$2:$A$16,Sheet1!$C$2:$C$16) -> Christian Hynek | C9: 103.75 | D9: 350.49 | E9: =TRUE -> TRUE | F9: =IF(E9, $B$37 * MAX(0, (C9 - 2/3*$B$23) / (1/3*$B$23)), 0) -> 384.52411 | G9: =IF(E9, $B$38, $B$38 * (D9/$B$30)) -> 333.33333 | H9: =Day_1[[#This Row],[Speed Pt]]+Day_1[[#This Row],[Dist Pt]] -> 717.85744 | I9: 0
A10: EX | B10: =_xlfn.XLOOKUP(Day_1[[#This Row],[Glider]],Sheet1!$A$2:$A$16,Sheet1!$C$2:$C$16) -> Tomas Rendla | C10: 101.15 | D10: 330.72 | E10: =TRUE -> TRUE | F10: =IF(E10, $B$37 * MAX(0, (C10 - 2/3*$B$23) / (1/3*$B$23)), 0) -> 341.47418 | G10: =IF(E10, $B$38, $B$38 * (D10/$B$30)) -> 333.33333 | H10: =Day_1[[#This Row],[Speed Pt]]+Day_1[[#This Row],[Dist Pt]] -> 674.80752 | I10: 0
A11: 1E | B11: =_xlfn.XLOOKUP(Day_1[[#This Row],[Glider]],Sheet1!$A$2:$A$16,Sheet1!$C$2:$C$16) -> Russell Cheetham | C11: 100.57 | D11: 315.75 | E11: =TRUE -> TRUE | F11: =IF(E11, $B$37 * MAX(0, (C11 - 2/3*$B$23) / (1/3*$B$23)), 0) -> 331.87074 | G11: =IF(E11, $B$38, $B$38 * (D11/$B$30)) -> 333.33333 | H11: =Day_1[[#This Row],[Speed Pt]]+Day_1[[#This Row],[Dist Pt]] -> 665.20407 | I11: 0
A12: ZFI | B12: =_xlfn.XLOOKUP(Day_1[[#This Row],[Glider]],Sheet1!$A$2:$A$16,Sheet1!$C$2:$C$16) -> Jiri Kusbach | C12: 99.64 | D12: 329.37 | E12: =TRUE -> TRUE | F12: =IF(E12, $B$37 * MAX(0, (C12 - 2/3*$B$23) / (1/3*$B$23)), 0) -> 316.47211 | G12: =IF(E12, $B$38, $B$38 * (D12/$B$30)) -> 333.33333 | H12: =Day_1[[#This Row],[Speed Pt]]+Day_1[[#This Row],[Dist Pt]] -> 649.80545 | I12: 0
A13: UFO | B13: =_xlfn.XLOOKUP(Day_1[[#This Row],[Glider]],Sheet1!$A$2:$A$16,Sheet1!$C$2:$C$16) -> Max Leenders | C13: 98.05 | D13: 315.11 | E13: =TRUE -> TRUE | F13: =IF(E13, $B$37 * MAX(0, (C13 - 2/3*$B$23) / (1/3*$B$23)), 0) -> 290.14543 | G13: =IF(E13, $B$38, $B$38 * (D13/$B$30)) -> 333.33333 | H13: =Day_1[[#This Row],[Speed Pt]]+Day_1[[#This Row],[Dist Pt]] -> 623.47876 | I13: 0
A14: 4D | B14: =_xlfn.XLOOKUP(Day_1[[#This Row],[Glider]],Sheet1!$A$2:$A$16,Sheet1!$C$2:$C$16) -> David Jansen | C14: 96.69 | D14: 308.05 | E14: =TRUE -> TRUE | F14: =IF(E14, $B$37 * MAX(0, (C14 - 2/3*$B$23) / (1/3*$B$23)), 0) -> 267.62701 | G14: =IF(E14, $B$38, $B$38 * (D14/$B$30)) -> 333.33333 | H14: =Day_1[[#This Row],[Speed Pt]]+Day_1[[#This Row],[Dist Pt]] -> 600.96034 | I14: 0
A15: OG | B15: =_xlfn.XLOOKUP(Day_1[[#This Row],[Glider]],Sheet1!$A$2:$A$16,Sheet1!$C$2:$C$16) -> Oscar Goudriaan | C15: 91.97 | D15: 322.92 | E15: =TRUE -> TRUE | F15: =IF(E15, $B$37 * MAX(0, (C15 - 2/3*$B$23) / (1/3*$B$23)), 0) -> 189.47485 | G15: =IF(E15, $B$38, $B$38 * (D15/$B$30)) -> 333.33333 | H15: =Day_1[[#This Row],[Speed Pt]]+Day_1[[#This Row],[Dist Pt]] -> 522.80818 | I15: 0
F16: =IF(E16, $B$37 * MAX(0, (C16 - 2/3*$B$23) / (1/3*$B$23)), 0) -> 0 | G16: =IF(E16, $B$38, $B$38 * (D16/$B$30)) -> 0 | H16: =Day_1[[#This Row],[Speed Pt]]+Day_1[[#This Row],[Dist Pt]] -> 0
A21: DM | B21: 140
A22: D1 | B22: 350
A23: V0 | B23: =MAX(C2:C15) -> 120.79
A24: T0 | B24: =D2/C2*3600 -> 11392.499
A26: N | B26: =COUNT(C2:C15) -> 14
A27: N1 | B27: =COUNTIF(D2:D15, ">=" & 140) -> 14
A28: N3 | B28: =COUNTIF(E2:E15, TRUE) -> 14
A29: N2 | B29: =COUNTIFS(E2:E15, TRUE, C2:C15, ">" & 2/3*$B$23) -> 14
A30: D0 | B30: =MAX(D2:D15) -> 383.62
A32: PmaxDist | B32: =1250 * (B30/B22) - 250 -> 1120.0714
A33: PmaxTime | B33: =IF(B24<=0, 1000, (400*B24/3600) - 200) -> 1065.8333
A34: Pm | B34: =MIN(B32,B33,1000) -> 1000
A35: F | B35: =MIN(1.25 * B27/B26, 1) -> 1
A36: Fcr | B36: =IF(B27>0, MIN(1.2*(B29/B27)+0.6, 1), 1) -> 1
A37: Pvm | B37: =(2/3) * (B29/B26) * B34 -> 666.66667
A38: Pdm | B38: =B34-B37 -> 333.33333

Sheet T2
A1: Glider | B1: Pilot | C1: Speed | D1: Distance | E1: Finished | F1: Speed Pt | G1: Dist Pt | H1: TOTAL PT | I1: Penalty
A2: YY | B2: =_xlfn.XLOOKUP(Day_2[[#This Row],[Glider]],Sheet1!$A$2:$A$16,Sheet1!$C$2:$C$16) -> Sebastian Kawa | C2: 135.53 | D2: 542.62 | E2: =TRUE -> TRUE | F2: =IF(E2, $B$37 * MAX(0, (C2 - 2/3*$B$23) / (1/3*$B$23)), 0) -> 619.04762 | G2: =IF(E2, $B$38, $B$38 * (D2/$B$30)) -> 380.95238 | H2: =Day_2[[#This Row],[Speed Pt]]+Day_2[[#This Row],[Dist Pt]] -> 1000 | I2: 0
A3: FL | B3: =_xlfn.XLOOKUP(Day_2[[#This Row],[Glider]],Sheet1!$A$2:$A$16,Sheet1!$C$2:$C$16) -> Felipe Levin | C3: 131.57 | D3: 542.62 | E3: =TRUE -> TRUE | F3: =IF(E3, $B$37 * MAX(0, (C3 - 2/3*$B$23) / (1/3*$B$23)), 0) -> 564.78446 | G3: =IF(E3, $B$38, $B$38 * (D3/$B$30)) -> 380.95238 | H3: =Day_2[[#This Row],[Speed Pt]]+Day_2[[#This Row],[Dist Pt]] -> 945.73684 | I3: 0
A4: OR | B4: =_xlfn.XLOOKUP(Day_2[[#This Row],[Glider]],Sheet1!$A$2:$A$16,Sheet1!$C$2:$C$16) -> Michael Sommer | C4: 130.38 | D4: 542.62 | E4: =TRUE -> TRUE | F4: =IF(E4, $B$37 * MAX(0, (C4 - 2/3*$B$23) / (1/3*$B$23)), 0) -> 548.47811 | G4: =IF(E4, $B$38, $B$38 * (D4/$B$30)) -> 380.95238 | H4: =Day_2[[#This Row],[Speed Pt]]+Day_2[[#This Row],[Dist Pt]] -> 929.43049 | I4: 0
A5: EX | B5: =_xlfn.XLOOKUP(Day_2[[#This Row],[Glider]],Sheet1!$A$2:$A$16,Sheet1!$C$2:$C$16) -> Tomas Rendla | C5: 129.41 | D5: 542.62 | E5: =TRUE -> TRUE | F5: =IF(E5, $B$37 * MAX(0, (C5 - 2/3*$B$23) / (1/3*$B$23)), 0) -> 535.18638 | G5: =IF(E5, $B$38, $B$38 * (D5/$B$30)) -> 380.95238 | H5: =Day_2[[#This Row],[Speed Pt]]+Day_2[[#This Row],[Dist Pt]] -> 916.13876 | I5: 0
A6: 1E | B6: =_xlfn.XLOOKUP(Day_2[[#This Row],[Glider]],Sheet1!$A$2:$A$16,Sheet1!$C$2:$C$16) -> Russell Cheetham | C6: 128.52 | D6: 542.62 | E6: =TRUE -> TRUE | F6: =IF(E6, $B$37 * MAX(0, (C6 - 2/3*$B$23) / (1/3*$B$23)), 0) -> 522.99087 | G6: =IF(E6, $B$38, $B$38 * (D6/$B$30)) -> 380.95238 | H6: =Day_2[[#This Row],[Speed Pt]]+Day_2[[#This Row],[Dist Pt]] -> 903.94325 | I6: 0
A7: 72 | B7: =_xlfn.XLOOKUP(Day_2[[#This Row],[Glider]],Sheet1!$A$2:$A$16,Sheet1!$C$2:$C$16) -> Sylvain Gerbaud | C7: 122.35 | D7: 542.62 | E7: =TRUE -> TRUE | F7: =IF(E7, $B$37 * MAX(0, (C7 - 2/3*$B$23) / (1/3*$B$23)), 0) -> 438.44448 | G7: =IF(E7, $B$38, $B$38 * (D7/$B$30)) -> 380.95238 | H7: =Day_2[[#This Row],[Speed Pt]]+Day_2[[#This Row],[Dist Pt]] -> 819.39687 | I7: 0
A8: UFO | B8: =_xlfn.XLOOKUP(Day_2[[#This Row],[Glider]],Sheet1!$A$2:$A$16,Sheet1!$C$2:$C$16) -> Max Leenders | C8: 119.47 | D8: 542.62 | E8: =TRUE -> TRUE | F8: =IF(E8, $B$37 * MAX(0, (C8 - 2/3*$B$23) / (1/3*$B$23)), 0) -> 398.98037 | G8: =IF(E8, $B$38, $B$38 * (D8/$B$30)) -> 380.95238 | H8: =Day_2[[#This Row],[Speed Pt]]+Day_2[[#This Row],[Dist Pt]] -> 779.93275 | I8: 0
A9: IP3 | B9: =_xlfn.XLOOKUP(Day_2[[#This Row],[Glider]],Sheet1!$A$2:$A$16,Sheet1!$C$2:$C$16) -> Pierre de Broqueville | C9: 117.61 | D9: 542.62 | E9: =TRUE -> TRUE | F9: =IF(E9, $B$37 * MAX(0, (C9 - 2/3*$B$23) / (1/3*$B$23)), 0) -> 373.49313 | G9: =IF(E9, $B$38, $B$38 * (D9/$B$30)) -> 380.95238 | H9: =Day_2[[#This Row],[Speed Pt]]+Day_2[[#This Row],[Dist Pt]] -> 754.44551 | I9: 0
A10: 5 | B10: =_xlfn.XLOOKUP(Day_2[[#This Row],[Glider]],Sheet1!$A$2:$A$16,Sheet1!$C$2:$C$16) -> Laurent Aboulin | C10: 117.52 | D10: 542.62 | E10: =TRUE -> TRUE | F10: =IF(E10, $B$37 * MAX(0, (C10 - 2/3*$B$23) / (1/3*$B$23)), 0) -> 372.25988 | G10: =IF(E10, $B$38, $B$38 * (D10/$B$30)) -> 380.95238 | H10: =Day_2[[#This Row],[Speed Pt]]+Day_2[[#This Row],[Dist Pt]] -> 753.21226 | I10: 0
A11: DD | B11: =_xlfn.XLOOKUP(Day_2[[#This Row],[Glider]],Sheet1!$A$2:$A$16,Sheet1!$C$2:$C$16) -> Christian Hynek | C11: 117.37 | D11: 542.62 | E11: =TRUE -> TRUE | F11: =IF(E11, $B$37 * MAX(0, (C11 - 2/3*$B$23) / (1/3*$B$23)), 0) -> 370.20445 | G11: =IF(E11, $B$38, $B$38 * (D11/$B$30)) -> 380.95238 | H11: =Day_2[[#This Row],[Speed Pt]]+Day_2[[#This Row],[Dist Pt]] -> 751.15683 | I11: 0
A12: ZFI | B12: =_xlfn.XLOOKUP(Day_2[[#This Row],[Glider]],Sheet1!$A$2:$A$16,Sheet1!$C$2:$C$16) -> Jiri Kusbach | C12: 116.47 | D12: 542.62 | E12: =TRUE -> TRUE | F12: =IF(E12, $B$37 * MAX(0, (C12 - 2/3*$B$23) / (1/3*$B$23)), 0) -> 357.87192 | G12: =IF(E12, $B$38, $B$38 * (D12/$B$30)) -> 380.95238 | H12: =Day_2[[#This Row],[Speed Pt]]+Day_2[[#This Row],[Dist Pt]] -> 738.8243 | I12: 0
A13: 4D | B13: =_xlfn.XLOOKUP(Day_2[[#This Row],[Glider]],Sheet1!$A$2:$A$16,Sheet1!$C$2:$C$16) -> David Jansen | C13: 116.26 | D13: 542.62 | E13: =TRUE -> TRUE | F13: =IF(E13, $B$37 * MAX(0, (C13 - 2/3*$B$23) / (1/3*$B$23)), 0) -> 354.99433 | G13: =IF(E13, $B$38, $B$38 * (D13/$B$30)) -> 380.95238 | H13: =Day_2[[#This Row],[Speed Pt]]+Day_2[[#This Row],[Dist Pt]] -> 735.94671 | I13: 0
A14: OG | B14: =_xlfn.XLOOKUP(Day_2[[#This Row],[Glider]],Sheet1!$A$2:$A$16,Sheet1!$C$2:$C$16) -> Oscar Goudriaan | C14: 116.03 | D14: 542.62 | E14: =TRUE -> TRUE | F14: =IF(E14, $B$37 * MAX(0, (C14 - 2/3*$B$23) / (1/3*$B$23)), 0) -> 351.84268 | G14: =IF(E14, $B$38, $B$38 * (D14/$B$30)) -> 380.95238 | H14: =Day_2[[#This Row],[Speed Pt]]+Day_2[[#This Row],[Dist Pt]] -> 732.79506 | I14: 0
A15: XR | B15: =_xlfn.XLOOKUP(Day_2[[#This Row],[Glider]],Sheet1!$A$2:$A$16,Sheet1!$C$2:$C$16) -> Bas Seijffert | D15: 505.85 | E15: =FALSE -> FALSE | F15: =IF(E15, $B$37 * MAX(0, (C15 - 2/3*$B$23) / (1/3*$B$23)), 0) -> 0 | G15: =IF(E15, $B$38, $B$38 * (D15/$B$30)) -> 355.1376 | H15: =Day_2[[#This Row],[Speed Pt]]+Day_2[[#This Row],[Dist Pt]] -> 355.1376 | I15: 0
A21: DM | B21: 140
A22: D1 | B22: 350
A23: V0 | B23: =MAX(C2:C15) -> 135.53
A24: T0 | B24: =D2/C2*3600 -> 14413.281
A26: N | B26: =COUNT(D2:D15) -> 14
A27: N1 | B27: =COUNTIF(D2:D15, ">=" & 140) -> 14
A28: N3 | B28: =COUNTIF(E2:E15, TRUE) -> 13
A29: N2 | B29: =COUNTIFS(E2:E15, TRUE, C2:C15, ">" & 2/3*$B$23) -> 13
A30: D0 | B30: =MAX(D2:D15) -> 542.62
A32: PmaxDist | B32: =1250 * (B30/B22) - 250 -> 1687.9286
A33: PmaxTime | B33: =IF(B24<=0, 1000, (400*B24/3600) - 200) -> 1401.4757
A34: Pm | B34: =MIN(B32,B33,1000) -> 1000
A35: F | B35: =MIN(1.25 * B27/B26, 1) -> 1
A36: Fcr | B36: =IF(B27>0, MIN(1.2*(B29/B27)+0.6, 1), 1) -> 1
A37: Pvm | B37: =(2/3) * (B29/B26) * B34 -> 619.04762
A38: Pdm | B38: =B34-B37 -> 380.95238

Sheet T3
A1: Glider | B1: Pilot | C1: Speed | D1: Distance | E1: Finished | F1: Speed Pt | G1: Dist Pt | H1: TOTAL PT | I1: Penalty
A2: 72 | B2: =_xlfn.XLOOKUP(Day_3[[#This Row],[Glider]],Sheet1!$A$2:$A$16,Sheet1!$C$2:$C$16) -> Sylvain Gerbaud | C2: 128.77 | D2: 334.49 | E2: =TRUE -> TRUE | F2: =IF(E2, $B$37 * MAX(0, (C2 - 2/3*$B$23) / (1/3*$B$23)), 0) -> 519.40004 | G2: =IF(E2, $B$38, $B$38 * (D2/$B$30)) -> 319.63079 | H2: =Day_3[[#This Row],[Speed Pt]]+Day_3[[#This Row],[Dist Pt]] -> 839.03083 | I2: 0
A3: YY | B3: =_xlfn.XLOOKUP(Day_3[[#This Row],[Glider]],Sheet1!$A$2:$A$16,Sheet1!$C$2:$C$16) -> Sebastian Kawa | C3: 126.97 | D3: 328.07 | E3: =TRUE -> TRUE | F3: =IF(E3, $B$37 * MAX(0, (C3 - 2/3*$B$23) / (1/3*$B$23)), 0) -> 497.61888 | G3: =IF(E3, $B$38, $B$38 * (D3/$B$30)) -> 319.63079 | H3: =Day_3[[#This Row],[Speed Pt]]+Day_3[[#This Row],[Dist Pt]] -> 817.24967 | I3: 0
A4: 5 | B4: =_xlfn.XLOOKUP(Day_3[[#This Row],[Glider]],Sheet1!$A$2:$A$16,Sheet1!$C$2:$C$16) -> Laurent Aboulin | C4: 126.93 | D4: 335.02 | E4: =TRUE -> TRUE | F4: =IF(E4, $B$37 * MAX(0, (C4 - 2/3*$B$23) / (1/3*$B$23)), 0) -> 497.13485 | G4: =IF(E4, $B$38, $B$38 * (D4/$B$30)) -> 319.63079 | H4: =Day_3[[#This Row],[Speed Pt]]+Day_3[[#This Row],[Dist Pt]] -> 816.76564 | I4: 0
A5: FL | B5: =_xlfn.XLOOKUP(Day_3[[#This Row],[Glider]],Sheet1!$A$2:$A$16,Sheet1!$C$2:$C$16) -> Felipe Levin | C5: 124.5 | D5: 337.1 | E5: =TRUE -> TRUE | F5: =IF(E5, $B$37 * MAX(0, (C5 - 2/3*$B$23) / (1/3*$B$23)), 0) -> 467.73028 | G5: =IF(E5, $B$38, $B$38 * (D5/$B$30)) -> 319.63079 | H5: =Day_3[[#This Row],[Speed Pt]]+Day_3[[#This Row],[Dist Pt]] -> 787.36107 | I5: 0
A6: OR | B6: =_xlfn.XLOOKUP(Day_3[[#This Row],[Glider]],Sheet1!$A$2:$A$16,Sheet1!$C$2:$C$16) -> Michael Sommer | C6: 124.39 | D6: 336.85 | E6: =TRUE -> TRUE | F6: =IF(E6, $B$37 * MAX(0, (C6 - 2/3*$B$23) / (1/3*$B$23)), 0) -> 466.39921 | G6: =IF(E6, $B$38, $B$38 * (D6/$B$30)) -> 319.63079 | H6: =Day_3[[#This Row],[Speed Pt]]+Day_3[[#This Row],[Dist Pt]] -> 786.03 | I6: 0
A7: OG | B7: =_xlfn.XLOOKUP(Day_3[[#This Row],[Glider]],Sheet1!$A$2:$A$16,Sheet1!$C$2:$C$16) -> Oscar Goudriaan | C7: 123.98 | D7: 320.21 | E7: =TRUE -> TRUE | F7: =IF(E7, $B$37 * MAX(0, (C7 - 2/3*$B$23) / (1/3*$B$23)), 0) -> 461.43795 | G7: =IF(E7, $B$38, $B$38 * (D7/$B$30)) -> 319.63079 | H7: =Day_3[[#This Row],[Speed Pt]]+Day_3[[#This Row],[Dist Pt]] -> 781.06874 | I7: 0
A8: 1E | B8: =_xlfn.XLOOKUP(Day_3[[#This Row],[Glider]],Sheet1!$A$2:$A$16,Sheet1!$C$2:$C$16) -> Russell Cheetham | C8: 121.34 | D8: 303.34 | E8: =TRUE -> TRUE | F8: =IF(E8, $B$37 * MAX(0, (C8 - 2/3*$B$23) / (1/3*$B$23)), 0) -> 429.49224 | G8: =IF(E8, $B$38, $B$38 * (D8/$B$30)) -> 319.63079 | H8: =Day_3[[#This Row],[Speed Pt]]+Day_3[[#This Row],[Dist Pt]] -> 749.12303 | I8: 0
A9: EX | B9: =_xlfn.XLOOKUP(Day_3[[#This Row],[Glider]],Sheet1!$A$2:$A$16,Sheet1!$C$2:$C$16) -> Tomas Rendla | C9: 119.75 | D9: 321.58 | E9: =TRUE -> TRUE | F9: =IF(E9, $B$37 * MAX(0, (C9 - 2/3*$B$23) / (1/3*$B$23)), 0) -> 410.25222 | G9: =IF(E9, $B$38, $B$38 * (D9/$B$30)) -> 319.63079 | H9: =Day_3[[#This Row],[Speed Pt]]+Day_3[[#This Row],[Dist Pt]] -> 729.88301 | I9: 0
A10: XR | B10: =_xlfn.XLOOKUP(Day_3[[#This Row],[Glider]],Sheet1!$A$2:$A$16,Sheet1!$C$2:$C$16) -> Bas Seijffert | C10: 118.91 | D10: 307.62 | E10: =TRUE -> TRUE | F10: =IF(E10, $B$37 * MAX(0, (C10 - 2/3*$B$23) / (1/3*$B$23)), 0) -> 400.08767 | G10: =IF(E10, $B$38, $B$38 * (D10/$B$30)) -> 319.63079 | H10: =Day_3[[#This Row],[Speed Pt]]+Day_3[[#This Row],[Dist Pt]] -> 719.71847 | I10: 0
A11: UFO | B11: =_xlfn.XLOOKUP(Day_3[[#This Row],[Glider]],Sheet1!$A$2:$A$16,Sheet1!$C$2:$C$16) -> Max Leenders | C11: 118.62 | D11: 302.23 | E11: =TRUE -> TRUE | F11: =IF(E11, $B$37 * MAX(0, (C11 - 2/3*$B$23) / (1/3*$B$23)), 0) -> 396.57849 | G11: =IF(E11, $B$38, $B$38 * (D11/$B$30)) -> 319.63079 | H11: =Day_3[[#This Row],[Speed Pt]]+Day_3[[#This Row],[Dist Pt]] -> 716.20928 | I11: 0
A12: IP3 | B12: =_xlfn.XLOOKUP(Day_3[[#This Row],[Glider]],Sheet1!$A$2:$A$16,Sheet1!$C$2:$C$16) -> Pierre de Broqueville | C12: 118.32 | D12: 305.98 | E12: =TRUE -> TRUE | F12: =IF(E12, $B$37 * MAX(0, (C12 - 2/3*$B$23) / (1/3*$B$23)), 0) -> 392.94829 | G12: =IF(E12, $B$38, $B$38 * (D12/$B$30)) -> 319.63079 | H12: =Day_3[[#This Row],[Speed Pt]]+Day_3[[#This Row],[Dist Pt]] -> 712.57909 | I12: 0
A13: ZFI | B13: =_xlfn.XLOOKUP(Day_3[[#This Row],[Glider]],Sheet1!$A$2:$A$16,Sheet1!$C$2:$C$16) -> Jiri Kusbach | C13: 117.02 | D13: 317.25 | E13: =TRUE -> TRUE | F13: =IF(E13, $B$37 * MAX(0, (C13 - 2/3*$B$23) / (1/3*$B$23)), 0) -> 377.21745 | G13: =IF(E13, $B$38, $B$38 * (D13/$B$30)) -> 319.63079 | H13: =Day_3[[#This Row],[Speed Pt]]+Day_3[[#This Row],[Dist Pt]] -> 696.84825 | I13: 0
A14: DD | B14: =_xlfn.XLOOKUP(Day_3[[#This Row],[Glider]],Sheet1!$A$2:$A$16,Sheet1!$C$2:$C$16) -> Christian Hynek | C14: 109.7 | D14: 291.93 | E14: =TRUE -> TRUE | F14: =IF(E14, $B$37 * MAX(0, (C14 - 2/3*$B$23) / (1/3*$B$23)), 0) -> 288.64073 | G14: =IF(E14, $B$38, $B$38 * (D14/$B$30)) -> 319.63079 | H14: =Day_3[[#This Row],[Speed Pt]]+Day_3[[#This Row],[Dist Pt]] -> 608.27152 | I14: 0
A15: 4D | B15: =_xlfn.XLOOKUP(Day_3[[#This Row],[Glider]],Sheet1!$A$2:$A$16,Sheet1!$C$2:$C$16) -> David Jansen | D15: 0
A21: DM | B21: 140
A22: D1 | B22: 350
A23: V0 | B23: =MAX(C2:C15) -> 128.77
A24: T0 | B24: =D2/C2*3600 -> 9351.2775
A26: N | B26: =COUNT(D2:D15) -> 14
A27: N1 | B27: =COUNTIF(D2:D15, ">=" & 140) -> 13
A28: N3 | B28: =COUNTIF(E2:E15, TRUE) -> 13
A29: N2 | B29: =COUNTIFS(E2:E15, TRUE, C2:C15, ">" & 2/3*$B$23) -> 13
A30: D0 | B30: =MAX(D2:D15) -> 337.1
A32: PmaxDist | B32: =1250 * (B30/B22) - 250 -> 953.92857
A33: PmaxTime | B33: =IF(B24<=0, 1000, (400*B24/3600) - 200) -> 839.03083
A34: Pm | B34: =MIN(B32,B33,1000) -> 839.03083
A35: F | B35: =MIN(1.25 * B27/B26, 1) -> 1
A36: Fcr | B36: =IF(B27>0, MIN(1.2*(B29/B27)+0.6, 1), 1) -> 1
A37: Pvm | B37: =(2/3) * (B29/B26) * B34 -> 519.40004
A38: Pdm | B38: =B34-B37 -> 319.63079

Sheet T4
A1: Glider | B1: Pilot | C1: Speed | D1: Distance | E1: Finished | F1: Speed Pt | G1: Dist Pt | H1: TOTAL PT | I1: Penalty
A2: FL | B2: =_xlfn.XLOOKUP(Day_4[[#This Row],[Glider]],Sheet1!$A$2:$A$16,Sheet1!$C$2:$C$16) -> Felipe Levin | C2: 122.63 | D2: 562.68 | E2: =TRUE -> TRUE | F2: =IF(E2, $B$37 * MAX(0, (C2 - 2/3*$B$23) / (1/3*$B$23)), 0) -> 666.66667 | G2: =IF(E2, $B$38, $B$38 * (D2/$B$30)) -> 333.33333 | H2: =Day_4[[#This Row],[Speed Pt]]+Day_4[[#This Row],[Dist Pt]] -> 1000 | I2: 0
A3: YY | B3: =_xlfn.XLOOKUP(Day_4[[#This Row],[Glider]],Sheet1!$A$2:$A$16,Sheet1!$C$2:$C$16) -> Sebastian Kawa | C3: 122.55 | D3: 562.68 | E3: =TRUE -> TRUE | F3: =IF(E3, $B$37 * MAX(0, (C3 - 2/3*$B$23) / (1/3*$B$23)), 0) -> 665.36193 | G3: =IF(E3, $B$38, $B$38 * (D3/$B$30)) -> 333.33333 | H3: =Day_4[[#This Row],[Speed Pt]]+Day_4[[#This Row],[Dist Pt]] -> 998.69526 | I3: 0
A4: OR | B4: =_xlfn.XLOOKUP(Day_4[[#This Row],[Glider]],Sheet1!$A$2:$A$16,Sheet1!$C$2:$C$16) -> Michael Sommer | C4: 122.37 | D4: 562.68 | E4: =TRUE -> TRUE | F4: =IF(E4, $B$37 * MAX(0, (C4 - 2/3*$B$23) / (1/3*$B$23)), 0) -> 662.42627 | G4: =IF(E4, $B$38, $B$38 * (D4/$B$30)) -> 333.33333 | H4: =Day_4[[#This Row],[Speed Pt]]+Day_4[[#This Row],[Dist Pt]] -> 995.7596 | I4: 0
A5: 72 | B5: =_xlfn.XLOOKUP(Day_4[[#This Row],[Glider]],Sheet1!$A$2:$A$16,Sheet1!$C$2:$C$16) -> Sylvain Gerbaud | C5: 115.97 | D5: 562.68 | E5: =TRUE -> TRUE | F5: =IF(E5, $B$37 * MAX(0, (C5 - 2/3*$B$23) / (1/3*$B$23)), 0) -> 558.04724 | G5: =IF(E5, $B$38, $B$38 * (D5/$B$30)) -> 333.33333 | H5: =Day_4[[#This Row],[Speed Pt]]+Day_4[[#This Row],[Dist Pt]] -> 891.38058 | I5: 0
A6: 5 | B6: =_xlfn.XLOOKUP(Day_4[[#This Row],[Glider]],Sheet1!$A$2:$A$16,Sheet1!$C$2:$C$16) -> Laurent Aboulin | C6: 115.89 | D6: 562.68 | E6: =TRUE -> TRUE | F6: =IF(E6, $B$37 * MAX(0, (C6 - 2/3*$B$23) / (1/3*$B$23)), 0) -> 556.7425 | G6: =IF(E6, $B$38, $B$38 * (D6/$B$30)) -> 333.33333 | H6: =Day_4[[#This Row],[Speed Pt]]+Day_4[[#This Row],[Dist Pt]] -> 890.07584 | I6: 0
A7: 1E | B7: =_xlfn.XLOOKUP(Day_4[[#This Row],[Glider]],Sheet1!$A$2:$A$16,Sheet1!$C$2:$C$16) -> Russell Cheetham | C7: 114.08 | D7: 562.68 | E7: =TRUE -> TRUE | F7: =IF(E7, $B$37 * MAX(0, (C7 - 2/3*$B$23) / (1/3*$B$23)), 0) -> 527.22281 | G7: =IF(E7, $B$38, $B$38 * (D7/$B$30)) -> 333.33333 | H7: =Day_4[[#This Row],[Speed Pt]]+Day_4[[#This Row],[Dist Pt]] -> 860.55614 | I7: 0
A8: IP3 | B8: =_xlfn.XLOOKUP(Day_4[[#This Row],[Glider]],Sheet1!$A$2:$A$16,Sheet1!$C$2:$C$16) -> Pierre de Broqueville | C8: 113.24 | D8: 562.68 | E8: =TRUE -> TRUE | F8: =IF(E8, $B$37 * MAX(0, (C8 - 2/3*$B$23) / (1/3*$B$23)), 0) -> 513.52306 | G8: =IF(E8, $B$38, $B$38 * (D8/$B$30)) -> 333.33333 | H8: =Day_4[[#This Row],[Speed Pt]]+Day_4[[#This Row],[Dist Pt]] -> 846.8564 | I8: 0
A9: OG | B9: =_xlfn.XLOOKUP(Day_4[[#This Row],[Glider]],Sheet1!$A$2:$A$16,Sheet1!$C$2:$C$16) -> Oscar Goudriaan | C9: 113.06 | D9: 562.68 | E9: =TRUE -> TRUE | F9: =IF(E9, $B$37 * MAX(0, (C9 - 2/3*$B$23) / (1/3*$B$23)), 0) -> 510.5874 | G9: =IF(E9, $B$38, $B$38 * (D9/$B$30)) -> 333.33333 | H9: =Day_4[[#This Row],[Speed Pt]]+Day_4[[#This Row],[Dist Pt]] -> 843.92074 | I9: 0
A10: UFO | B10: =_xlfn.XLOOKUP(Day_4[[#This Row],[Glider]],Sheet1!$A$2:$A$16,Sheet1!$C$2:$C$16) -> Max Leenders | C10: 109.96 | D10: 562.68 | E10: =TRUE -> TRUE | F10: =IF(E10, $B$37 * MAX(0, (C10 - 2/3*$B$23) / (1/3*$B$23)), 0) -> 460.02881 | G10: =IF(E10, $B$38, $B$38 * (D10/$B$30)) -> 333.33333 | H10: =Day_4[[#This Row],[Speed Pt]]+Day_4[[#This Row],[Dist Pt]] -> 793.36215 | I10: 0
A11: XR | B11: =_xlfn.XLOOKUP(Day_4[[#This Row],[Glider]],Sheet1!$A$2:$A$16,Sheet1!$C$2:$C$16) -> Bas Seijffert | C11: 108.44 | D11: 562.68 | E11: =TRUE -> TRUE | F11: =IF(E11, $B$37 * MAX(0, (C11 - 2/3*$B$23) / (1/3*$B$23)), 0) -> 435.23879 | G11: =IF(E11, $B$38, $B$38 * (D11/$B$30)) -> 333.33333 | H11: =Day_4[[#This Row],[Speed Pt]]+Day_4[[#This Row],[Dist Pt]] -> 768.57213 | I11: 0
A12: ZFI | B12: =_xlfn.XLOOKUP(Day_4[[#This Row],[Glider]],Sheet1!$A$2:$A$16,Sheet1!$C$2:$C$16) -> Jiri Kusbach | C12: 106.04 | D12: 562.68 | E12: =TRUE -> TRUE | F12: =IF(E12, $B$37 * MAX(0, (C12 - 2/3*$B$23) / (1/3*$B$23)), 0) -> 396.09666 | G12: =IF(E12, $B$38, $B$38 * (D12/$B$30)) -> 333.33333 | H12: =Day_4[[#This Row],[Speed Pt]]+Day_4[[#This Row],[Dist Pt]] -> 729.42999 | I12: 0
A13: DD | B13: =_xlfn.XLOOKUP(Day_4[[#This Row],[Glider]],Sheet1!$A$2:$A$16,Sheet1!$C$2:$C$16) -> Christian Hynek | C13: 101.46 | D13: 562.68 | E13: =TRUE -> TRUE | F13: =IF(E13, $B$37 * MAX(0, (C13 - 2/3*$B$23) / (1/3*$B$23)), 0) -> 321.40042 | G13: =IF(E13, $B$38, $B$38 * (D13/$B$30)) -> 333.33333 | H13: =Day_4[[#This Row],[Speed Pt]]+Day_4[[#This Row],[Dist Pt]] -> 654.73375 | I13: 0
A14: EX | B14: =_xlfn.XLOOKUP(Day_4[[#This Row],[Glider]],Sheet1!$A$2:$A$16,Sheet1!$C$2:$C$16) -> Tomas Rendla | C14: 99.42 | D14: 562.68 | E14: =TRUE -> TRUE | F14: =IF(E14, $B$37 * MAX(0, (C14 - 2/3*$B$23) / (1/3*$B$23)), 0) -> 288.1296 | G14: =IF(E14, $B$38, $B$38 * (D14/$B$30)) -> 333.33333 | H14: =Day_4[[#This Row],[Speed Pt]]+Day_4[[#This Row],[Dist Pt]] -> 621.46294 | I14: 0
A15: 4D | B15: =_xlfn.XLOOKUP(Day_4[[#This Row],[Glider]],Sheet1!$A$2:$A$16,Sheet1!$C$2:$C$16) -> David Jansen
A21: DM | B21: 140
A22: D1 | B22: 350
A23: V0 | B23: =MAX(C2:C15) -> 122.63
A24: T0 | B24: =D2/C2*3600 -> 16518.372
A26: N | B26: =COUNT(D2:D15) -> 13
A27: N1 | B27: =COUNTIF(D2:D15, ">=" & 140) -> 13
A28: N3 | B28: =COUNTIF(E2:E15, TRUE) -> 13
A29: N2 | B29: =COUNTIFS(E2:E15, TRUE, C2:C15, ">" & 2/3*$B$23) -> 13
A30: D0 | B30: =MAX(D2:D15) -> 562.68
A32: PmaxDist | B32: =1250 * (B30/B22) - 250 -> 1759.5714
A33: PmaxTime | B33: =IF(B24<=0, 1000, (400*B24/3600) - 200) -> 1635.3747
A34: Pm | B34: =MIN(B32,B33,1000) -> 1000
A35: F | B35: =MIN(1.25 * B27/B26, 1) -> 1
A36: Fcr | B36: =IF(B27>0, MIN(1.2*(B29/B27)+0.6, 1), 1) -> 1
A37: Pvm | B37: =(2/3) * (B29/B26) * B34 -> 666.66667
A38: Pdm | B38: =B34-B37 -> 333.33333

Sheet T5
A1: Glider | B1: Pilot | C1: Speed | D1: Distance | E1: Finished | F1: Speed Pt | G1: Dist Pt | H1: TOTAL PT | I1: Penalty
A2: OR | B2: =_xlfn.XLOOKUP(Day_5[[#This Row],[Glider]],Sheet1!$A$2:$A$16,Sheet1!$C$2:$C$16) -> Michael Sommer | C2: 119.96 | D2: 576.3 | E2: =TRUE -> TRUE | F2: =IF(E2, $B$37 * MAX(0, (C2 - 2/3*$B$23) / (1/3*$B$23)), 0) -> 619.04762 | G2: =IF(E2, $B$38, $B$38 * (D2/$B$30)) -> 380.95238 | H2: =Day_5[[#This Row],[Speed Pt]]+Day_5[[#This Row],[Dist Pt]] -> 1000 | I2: 0
A3: FL | B3: =_xlfn.XLOOKUP(Day_5[[#This Row],[Glider]],Sheet1!$A$2:$A$16,Sheet1!$C$2:$C$16) -> Felipe Levin | C3: 119.04 | D3: 576.3 | E3: =TRUE -> TRUE | F3: =IF(E3, $B$37 * MAX(0, (C3 - 2/3*$B$23) / (1/3*$B$23)), 0) -> 604.80478 | G3: =IF(E3, $B$38, $B$38 * (D3/$B$30)) -> 380.95238 | H3: =Day_5[[#This Row],[Speed Pt]]+Day_5[[#This Row],[Dist Pt]] -> 985.75716 | I3: 0
A4: 72 | B4: =_xlfn.XLOOKUP(Day_5[[#This Row],[Glider]],Sheet1!$A$2:$A$16,Sheet1!$C$2:$C$16) -> Sylvain Gerbaud | C4: 116.3 | D4: 576.3 | E4: =TRUE -> TRUE | F4: =IF(E4, $B$37 * MAX(0, (C4 - 2/3*$B$23) / (1/3*$B$23)), 0) -> 562.38587 | G4: =IF(E4, $B$38, $B$38 * (D4/$B$30)) -> 380.95238 | H4: =Day_5[[#This Row],[Speed Pt]]+Day_5[[#This Row],[Dist Pt]] -> 943.33826 | I4: 0
A5: UFO | B5: =_xlfn.XLOOKUP(Day_5[[#This Row],[Glider]],Sheet1!$A$2:$A$16,Sheet1!$C$2:$C$16) -> Max Leenders | C5: 110.53 | D5: 576.3 | E5: =TRUE -> TRUE | F5: =IF(E5, $B$37 * MAX(0, (C5 - 2/3*$B$23) / (1/3*$B$23)), 0) -> 473.05848 | G5: =IF(E5, $B$38, $B$38 * (D5/$B$30)) -> 380.95238 | H5: =Day_5[[#This Row],[Speed Pt]]+Day_5[[#This Row],[Dist Pt]] -> 854.01086 | I5: 0
A6: YY | B6: =_xlfn.XLOOKUP(Day_5[[#This Row],[Glider]],Sheet1!$A$2:$A$16,Sheet1!$C$2:$C$16) -> Sebastian Kawa | C6: 110.24 | D6: 576.3 | E6: =TRUE -> TRUE | F6: =IF(E6, $B$37 * MAX(0, (C6 - 2/3*$B$23) / (1/3*$B$23)), 0) -> 468.56889 | G6: =IF(E6, $B$38, $B$38 * (D6/$B$30)) -> 380.95238 | H6: =Day_5[[#This Row],[Speed Pt]]+Day_5[[#This Row],[Dist Pt]] -> 849.52127 | I6: 0
A7: IP3 | B7: =_xlfn.XLOOKUP(Day_5[[#This Row],[Glider]],Sheet1!$A$2:$A$16,Sheet1!$C$2:$C$16) -> Pierre de Broqueville | C7: 110.23 | D7: 576.3 | E7: =TRUE -> TRUE | F7: =IF(E7, $B$37 * MAX(0, (C7 - 2/3*$B$23) / (1/3*$B$23)), 0) -> 468.41407 | G7: =IF(E7, $B$38, $B$38 * (D7/$B$30)) -> 380.95238 | H7: =Day_5[[#This Row],[Speed Pt]]+Day_5[[#This Row],[Dist Pt]] -> 849.36646 | I7: 0
A8: EX | B8: =_xlfn.XLOOKUP(Day_5[[#This Row],[Glider]],Sheet1!$A$2:$A$16,Sheet1!$C$2:$C$16) -> Tomas Rendla | C8: 109.52 | D8: 576.3 | E8: =TRUE -> TRUE | F8: =IF(E8, $B$37 * MAX(0, (C8 - 2/3*$B$23) / (1/3*$B$23)), 0) -> 457.42232 | G8: =IF(E8, $B$38, $B$38 * (D8/$B$30)) -> 380.95238 | H8: =Day_5[[#This Row],[Speed Pt]]+Day_5[[#This Row],[Dist Pt]] -> 838.3747 | I8: 0
A9: 5 | B9: =_xlfn.XLOOKUP(Day_5[[#This Row],[Glider]],Sheet1!$A$2:$A$16,Sheet1!$C$2:$C$16) -> Laurent Aboulin | C9: 108.61 | D9: 576.3 | E9: =TRUE -> TRUE | F9: =IF(E9, $B$37 * MAX(0, (C9 - 2/3*$B$23) / (1/3*$B$23)), 0) -> 443.33429 | G9: =IF(E9, $B$38, $B$38 * (D9/$B$30)) -> 380.95238 | H9: =Day_5[[#This Row],[Speed Pt]]+Day_5[[#This Row],[Dist Pt]] -> 824.28667 | I9: 0
A10: 1E | B10: =_xlfn.XLOOKUP(Day_5[[#This Row],[Glider]],Sheet1!$A$2:$A$16,Sheet1!$C$2:$C$16) -> Russell Cheetham | C10: 107.26 | D10: 576.3 | E10: =TRUE -> TRUE | F10: =IF(E10, $B$37 * MAX(0, (C10 - 2/3*$B$23) / (1/3*$B$23)), 0) -> 422.43446 | G10: =IF(E10, $B$38, $B$38 * (D10/$B$30)) -> 380.95238 | H10: =Day_5[[#This Row],[Speed Pt]]+Day_5[[#This Row],[Dist Pt]] -> 803.38684 | I10: 0
A11: ZFI | B11: =_xlfn.XLOOKUP(Day_5[[#This Row],[Glider]],Sheet1!$A$2:$A$16,Sheet1!$C$2:$C$16) -> Jiri Kusbach | C11: 105.94 | D11: 576.3 | E11: =TRUE -> TRUE | F11: =IF(E11, $B$37 * MAX(0, (C11 - 2/3*$B$23) / (1/3*$B$23)), 0) -> 401.99908 | G11: =IF(E11, $B$38, $B$38 * (D11/$B$30)) -> 380.95238 | H11: =Day_5[[#This Row],[Speed Pt]]+Day_5[[#This Row],[Dist Pt]] -> 782.95146 | I11: 0
A12: OG | B12: =_xlfn.XLOOKUP(Day_5[[#This Row],[Glider]],Sheet1!$A$2:$A$16,Sheet1!$C$2:$C$16) -> Oscar Goudriaan | C12: 105.76 | D12: 576.3 | E12: =TRUE -> TRUE | F12: =IF(E12, $B$37 * MAX(0, (C12 - 2/3*$B$23) / (1/3*$B$23)), 0) -> 399.21244 | G12: =IF(E12, $B$38, $B$38 * (D12/$B$30)) -> 380.95238 | H12: =Day_5[[#This Row],[Speed Pt]]+Day_5[[#This Row],[Dist Pt]] -> 780.16482 | I12: 0
A13: XR | B13: =_xlfn.XLOOKUP(Day_5[[#This Row],[Glider]],Sheet1!$A$2:$A$16,Sheet1!$C$2:$C$16) -> Bas Seijffert | C13: 103.6 | D13: 576.3 | E13: =TRUE -> TRUE | F13: =IF(E13, $B$37 * MAX(0, (C13 - 2/3*$B$23) / (1/3*$B$23)), 0) -> 365.77272 | G13: =IF(E13, $B$38, $B$38 * (D13/$B$30)) -> 380.95238 | H13: =Day_5[[#This Row],[Speed Pt]]+Day_5[[#This Row],[Dist Pt]] -> 746.7251 | I13: 0
A14: DD | B14: =_xlfn.XLOOKUP(Day_5[[#This Row],[Glider]],Sheet1!$A$2:$A$16,Sheet1!$C$2:$C$16) -> Christian Hynek | C14: 98.71 | D14: 576.3 | E14: =TRUE -> TRUE | F14: =IF(E14, $B$37 * MAX(0, (C14 - 2/3*$B$23) / (1/3*$B$23)), 0) -> 290.06891 | G14: =IF(E14, $B$38, $B$38 * (D14/$B$30)) -> 380.95238 | H14: =Day_5[[#This Row],[Speed Pt]]+Day_5[[#This Row],[Dist Pt]] -> 671.02129 | I14: 0
A15: 4D | B15: =_xlfn.XLOOKUP(Day_5[[#This Row],[Glider]],Sheet1!$A$2:$A$16,Sheet1!$C$2:$C$16) -> David Jansen | D15: 86.82 | E15: =FALSE -> FALSE | F15: =IF(E15, $B$37 * MAX(0, (C15 - 2/3*$B$23) / (1/3*$B$23)), 0) -> 0 | G15: =IF(E15, $B$38, $B$38 * (D15/$B$30)) -> 57.390744 | H15: =Day_5[[#This Row],[Speed Pt]]+Day_5[[#This Row],[Dist Pt]] -> 57.390744
A21: DM | B21: 140
A22: D1 | B22: 350
A23: V0 | B23: =MAX(C2:C15) -> 119.96
A24: T0 | B24: =D2/C2*3600 -> 17294.765
A26: N | B26: =COUNT(D2:D15) -> 14
A27: N1 | B27: =COUNTIF(D2:D15, ">=" & 140) -> 13
A28: N3 | B28: =COUNTIF(E2:E15, TRUE) -> 13
A29: N2 | B29: =COUNTIFS(E2:E15, TRUE, C2:C15, ">" & 2/3*$B$23) -> 13
A30: D0 | B30: =MAX(D2:D15) -> 576.3
A32: PmaxDist | B32: =1250 * (B30/B22) - 250 -> 1808.2143
A33: PmaxTime | B33: =IF(B24<=0, 1000, (400*B24/3600) - 200) -> 1721.6405
A34: Pm | B34: =MIN(B32,B33,1000) -> 1000
A35: F | B35: =MIN(1.25 * B27/B26, 1) -> 1
A36: Fcr | B36: =IF(B27>0, MIN(1.2*(B29/B27)+0.6, 1), 1) -> 1
A37: Pvm | B37: =(2/3) * (B29/B26) * B34 -> 619.04762
A38: Pdm | B38: =B34-B37 -> 380.95238

Sheet T6
A1: Glider | B1: Pilot | C1: Speed | D1: Distance | E1: Finished | F1: Speed Pt | G1: Dist Pt | H1: TOTAL PT | I1: Penalty
A2: 72 | B2: =_xlfn.XLOOKUP(Day_6[[#This Row],[Glider]],Sheet1!$A$2:$A$16,Sheet1!$C$2:$C$16) -> Sylvain Gerbaud | C2: 122.53 | D2: 449.7 | E2: =TRUE -> TRUE | F2: =IF(E2, $B$37 * MAX(0, (C2 - 2/3*$B$23) / (1/3*$B$23)), 0) -> 571.42857 | G2: =IF(E2, $B$38, $B$38 * (D2/$B$30)) -> 428.57143 | H2: =Day_6[[#This Row],[Speed Pt]]+Day_6[[#This Row],[Dist Pt]] -> 1000 | I2: 0
A3: 5 | B3: =_xlfn.XLOOKUP(Day_6[[#This Row],[Glider]],Sheet1!$A$2:$A$16,Sheet1!$C$2:$C$16) -> Laurent Aboulin | C3: 120.77 | D3: 451.44 | E3: =TRUE -> TRUE | F3: =IF(E3, $B$37 * MAX(0, (C3 - 2/3*$B$23) / (1/3*$B$23)), 0) -> 546.80486 | G3: =IF(E3, $B$38, $B$38 * (D3/$B$30)) -> 428.57143 | H3: =Day_6[[#This Row],[Speed Pt]]+Day_6[[#This Row],[Dist Pt]] -> 975.37629 | I3: 0
A4: YY | B4: =_xlfn.XLOOKUP(Day_6[[#This Row],[Glider]],Sheet1!$A$2:$A$16,Sheet1!$C$2:$C$16) -> Sebastian Kawa | C4: 118.59 | D4: 434.33 | E4: =TRUE -> TRUE | F4: =IF(E4, $B$37 * MAX(0, (C4 - 2/3*$B$23) / (1/3*$B$23)), 0) -> 516.30504 | G4: =IF(E4, $B$38, $B$38 * (D4/$B$30)) -> 428.57143 | H4: =Day_6[[#This Row],[Speed Pt]]+Day_6[[#This Row],[Dist Pt]] -> 944.87647 | I4: 0
A5: ZFI | B5: =_xlfn.XLOOKUP(Day_6[[#This Row],[Glider]],Sheet1!$A$2:$A$16,Sheet1!$C$2:$C$16) -> Jiri Kusbach | C5: 116.58 | D5: 421.71 | E5: =TRUE -> TRUE | F5: =IF(E5, $B$37 * MAX(0, (C5 - 2/3*$B$23) / (1/3*$B$23)), 0) -> 488.18365 | G5: =IF(E5, $B$38, $B$38 * (D5/$B$30)) -> 428.57143 | H5: =Day_6[[#This Row],[Speed Pt]]+Day_6[[#This Row],[Dist Pt]] -> 916.75508 | I5: 0
A6: EX | B6: =_xlfn.XLOOKUP(Day_6[[#This Row],[Glider]],Sheet1!$A$2:$A$16,Sheet1!$C$2:$C$16) -> Tomas Rendla | C6: 115.86 | D6: 427.83 | E6: =TRUE -> TRUE | F6: =IF(E6, $B$37 * MAX(0, (C6 - 2/3*$B$23) / (1/3*$B$23)), 0) -> 478.11032 | G6: =IF(E6, $B$38, $B$38 * (D6/$B$30)) -> 428.57143 | H6: =Day_6[[#This Row],[Speed Pt]]+Day_6[[#This Row],[Dist Pt]] -> 906.68175 | I6: 0
A7: XR | B7: =_xlfn.XLOOKUP(Day_6[[#This Row],[Glider]],Sheet1!$A$2:$A$16,Sheet1!$C$2:$C$16) -> Bas Seijffert | C7: 112.45 | D7: 405.69 | E7: =TRUE -> TRUE | F7: =IF(E7, $B$37 * MAX(0, (C7 - 2/3*$B$23) / (1/3*$B$23)), 0) -> 430.40188 | G7: =IF(E7, $B$38, $B$38 * (D7/$B$30)) -> 428.57143 | H7: =Day_6[[#This Row],[Speed Pt]]+Day_6[[#This Row],[Dist Pt]] -> 858.97331 | I7: 0
A8: IP3 | B8: =_xlfn.XLOOKUP(Day_6[[#This Row],[Glider]],Sheet1!$A$2:$A$16,Sheet1!$C$2:$C$16) -> Pierre de Broqueville | C8: 110.25 | D8: 444.98 | E8: =TRUE -> TRUE | F8: =IF(E8, $B$37 * MAX(0, (C8 - 2/3*$B$23) / (1/3*$B$23)), 0) -> 399.62225 | G8: =IF(E8, $B$38, $B$38 * (D8/$B$30)) -> 428.57143 | H8: =Day_6[[#This Row],[Speed Pt]]+Day_6[[#This Row],[Dist Pt]] -> 828.19368 | I8: 0
A9: OR | B9: =_xlfn.XLOOKUP(Day_6[[#This Row],[Glider]],Sheet1!$A$2:$A$16,Sheet1!$C$2:$C$16) -> Michael Sommer | C9: 108.03 | D9: 427.76 | E9: =IF(Day_6[[#This Row],[Speed]]>0,TRUE,FALSE) -> TRUE | F9: =IF(E9, $B$37 * MAX(0, (C9 - 2/3*$B$23) / (1/3*$B$23)), 0) -> 368.5628 | G9: =IF(E9, $B$38, $B$38 * (D9/$B$30)) -> 428.57143 | H9: =Day_6[[#This Row],[Speed Pt]]+Day_6[[#This Row],[Dist Pt]] -> 797.13423 | I9: 0
A10: 1E | B10: =_xlfn.XLOOKUP(Day_6[[#This Row],[Glider]],Sheet1!$A$2:$A$16,Sheet1!$C$2:$C$16) -> Russell Cheetham | C10: 107.42 | D10: 425.63 | E10: =IF(Day_6[[#This Row],[Speed]]>0,TRUE,FALSE) -> TRUE | F10: =IF(E10, $B$37 * MAX(0, (C10 - 2/3*$B$23) / (1/3*$B$23)), 0) -> 360.02845 | G10: =IF(E10, $B$38, $B$38 * (D10/$B$30)) -> 428.57143 | H10: =Day_6[[#This Row],[Speed Pt]]+Day_6[[#This Row],[Dist Pt]] -> 788.59988 | I10: 0
A11: FL | B11: =_xlfn.XLOOKUP(Day_6[[#This Row],[Glider]],Sheet1!$A$2:$A$16,Sheet1!$C$2:$C$16) -> Felipe Levin | C11: 107.03 | D11: 426.02 | E11: =IF(Day_6[[#This Row],[Speed]]>0,TRUE,FALSE) -> TRUE | F11: =IF(E11, $B$37 * MAX(0, (C11 - 2/3*$B$23) / (1/3*$B$23)), 0) -> 354.57206 | G11: =IF(E11, $B$38, $B$38 * (D11/$B$30)) -> 428.57143 | H11: =Day_6[[#This Row],[Speed Pt]]+Day_6[[#This Row],[Dist Pt]] -> 783.14349 | I11: 0
A12: OG | B12: =_xlfn.XLOOKUP(Day_6[[#This Row],[Glider]],Sheet1!$A$2:$A$16,Sheet1!$C$2:$C$16) -> Oscar Goudriaan | C12: 102.87 | D12: 387.57 | E12: =IF(Day_6[[#This Row],[Speed]]>0,TRUE,FALSE) -> TRUE | F12: =IF(E12, $B$37 * MAX(0, (C12 - 2/3*$B$23) / (1/3*$B$23)), 0) -> 296.37057 | G12: =IF(E12, $B$38, $B$38 * (D12/$B$30)) -> 428.57143 | H12: =Day_6[[#This Row],[Speed Pt]]+Day_6[[#This Row],[Dist Pt]] -> 724.942 | I12: 0
A13: UFO | B13: =_xlfn.XLOOKUP(Day_6[[#This Row],[Glider]],Sheet1!$A$2:$A$16,Sheet1!$C$2:$C$16) -> Max Leenders | C13: 102.43 | D13: 379.97 | E13: =IF(Day_6[[#This Row],[Speed]]>0,TRUE,FALSE) -> TRUE | F13: =IF(E13, $B$37 * MAX(0, (C13 - 2/3*$B$23) / (1/3*$B$23)), 0) -> 290.21464 | G13: =IF(E13, $B$38, $B$38 * (D13/$B$30)) -> 428.57143 | H13: =Day_6[[#This Row],[Speed Pt]]+Day_6[[#This Row],[Dist Pt]] -> 718.78607 | I13: 0
A14: DD | B14: =_xlfn.XLOOKUP(Day_6[[#This Row],[Glider]],Sheet1!$A$2:$A$16,Sheet1!$C$2:$C$16) -> Christian Hynek | D14: 443.99 | E14: =IF(Day_6[[#This Row],[Speed]]>0,TRUE,FALSE) -> FALSE | F14: =IF(E14, $B$37 * MAX(0, (C14 - 2/3*$B$23) / (1/3*$B$23)), 0) -> 0 | G14: =IF(E14, $B$38, $B$38 * (D14/$B$30)) -> 421.49882 | H14: =Day_6[[#This Row],[Speed Pt]]+Day_6[[#This Row],[Dist Pt]] -> 421.49882 | I14: 0
A15: 4D | B15: =_xlfn.XLOOKUP(Day_6[[#This Row],[Glider]],Sheet1!$A$2:$A$16,Sheet1!$C$2:$C$16) -> David Jansen | D15: 305.52 | E15: =IF(Day_6[[#This Row],[Speed]]>0,TRUE,FALSE) -> FALSE | F15: =IF(E15, $B$37 * MAX(0, (C15 - 2/3*$B$23) / (1/3*$B$23)), 0) -> 0 | G15: =IF(E15, $B$38, $B$38 * (D15/$B$30)) -> 290.04329 | H15: =Day_6[[#This Row],[Speed Pt]]+Day_6[[#This Row],[Dist Pt]] -> 290.04329 | I15: 0
A21: DM | B21: 140
A22: D1 | B22: 350
A23: V0 | B23: =MAX(C2:C15) -> 122.53
A24: T0 | B24: =D2/C2*3600 -> 13212.438
A26: N | B26: =COUNT(D2:D15) -> 14
A27: N1 | B27: =COUNTIF(D2:D15, ">=" & 140) -> 14
A28: N3 | B28: =COUNTIF(E2:E15, TRUE) -> 12
A29: N2 | B29: =COUNTIFS(E2:E15, TRUE, C2:C15, ">" & 2/3*$B$23) -> 12
A30: D0 | B30: =MAX(D2:D15) -> 451.44
A32: PmaxDist | B32: =1250 * (B30/B22) - 250 -> 1362.2857
A33: PmaxTime | B33: =IF(B24<=0, 1000, (400*B24/3600) - 200) -> 1268.0486
A34: Pm | B34: =MIN(B32,B33,1000) -> 1000
A35: F | B35: =MIN(1.25 * B27/B26, 1) -> 1
A36: Fcr | B36: =IF(B27>0, MIN(1.2*(B29/B27)+0.6, 1), 1) -> 1
A37: Pvm | B37: =(2/3) * (B29/B26) * B34 -> 571.42857
A38: Pdm | B38: =B34-B37 -> 428.57143

Sheet T7
A1: Glider | B1: Pilot | C1: Speed | D1: Distance | E1: Finished | F1: Speed Pt | G1: Dist Pt | H1: TOTAL PT | I1: Penalty
A2: DD | B2: =_xlfn.XLOOKUP(Day_7[[#This Row],[Glider]],Sheet1!$A$2:$A$16,Sheet1!$C$2:$C$16) -> Christian Hynek | C2: 100.61 | D2: 259.79 | E2: =TRUE -> TRUE | F2: =IF(E2, $B$37 * MAX(0, (C2 - 2/3*$B$23) / (1/3*$B$23)), 0) -> 387.32653 | G2: =IF(E2, $B$38, $B$38 * (D2/$B$30)) -> 290.4949 | H2: =Day_7[[#This Row],[Speed Pt]]+Day_7[[#This Row],[Dist Pt]] -> 677.82143 | I2: 0
A3: XR | B3: =_xlfn.XLOOKUP(Day_7[[#This Row],[Glider]],Sheet1!$A$2:$A$16,Sheet1!$C$2:$C$16) -> Bas Seijffert | C3: 99.27 | D3: 249.84 | E3: =TRUE -> TRUE | F3: =IF(E3, $B$37 * MAX(0, (C3 - 2/3*$B$23) / (1/3*$B$23)), 0) -> 371.85041 | G3: =IF(E3, $B$38, $B$38 * (D3/$B$30)) -> 290.4949 | H3: =Day_7[[#This Row],[Speed Pt]]+Day_7[[#This Row],[Dist Pt]] -> 662.34531 | I3: 0
A4: YY | B4: =_xlfn.XLOOKUP(Day_7[[#This Row],[Glider]],Sheet1!$A$2:$A$16,Sheet1!$C$2:$C$16) -> Sebastian Kawa | C4: 98.28 | D4: 253.46 | E4: =TRUE -> TRUE | F4: =IF(E4, $B$37 * MAX(0, (C4 - 2/3*$B$23) / (1/3*$B$23)), 0) -> 360.41656 | G4: =IF(E4, $B$38, $B$38 * (D4/$B$30)) -> 290.4949 | H4: =Day_7[[#This Row],[Speed Pt]]+Day_7[[#This Row],[Dist Pt]] -> 650.91145 | I4: 0
A5: FL | B5: =_xlfn.XLOOKUP(Day_7[[#This Row],[Glider]],Sheet1!$A$2:$A$16,Sheet1!$C$2:$C$16) -> Felipe Levin | C5: 97.53 | D5: 259.39 | E5: =TRUE -> TRUE | F5: =IF(E5, $B$37 * MAX(0, (C5 - 2/3*$B$23) / (1/3*$B$23)), 0) -> 351.75455 | G5: =IF(E5, $B$38, $B$38 * (D5/$B$30)) -> 290.4949 | H5: =Day_7[[#This Row],[Speed Pt]]+Day_7[[#This Row],[Dist Pt]] -> 642.24945 | I5: 0
A6: OR | B6: =_xlfn.XLOOKUP(Day_7[[#This Row],[Glider]],Sheet1!$A$2:$A$16,Sheet1!$C$2:$C$16) -> Michael Sommer | C6: 96.29 | D6: 257.23 | E6: =TRUE -> TRUE | F6: =IF(E6, $B$37 * MAX(0, (C6 - 2/3*$B$23) / (1/3*$B$23)), 0) -> 337.43336 | G6: =IF(E6, $B$38, $B$38 * (D6/$B$30)) -> 290.4949 | H6: =Day_7[[#This Row],[Speed Pt]]+Day_7[[#This Row],[Dist Pt]] -> 627.92826 | I6: 0
A7: 72 | B7: =_xlfn.XLOOKUP(Day_7[[#This Row],[Glider]],Sheet1!$A$2:$A$16,Sheet1!$C$2:$C$16) -> Sylvain Gerbaud | C7: 93.12 | D7: 254.81 | E7: =TRUE -> TRUE | F7: =IF(E7, $B$37 * MAX(0, (C7 - 2/3*$B$23) / (1/3*$B$23)), 0) -> 300.82194 | G7: =IF(E7, $B$38, $B$38 * (D7/$B$30)) -> 290.4949 | H7: =Day_7[[#This Row],[Speed Pt]]+Day_7[[#This Row],[Dist Pt]] -> 591.31684 | I7: 0
A8: 5 | B8: =_xlfn.XLOOKUP(Day_7[[#This Row],[Glider]],Sheet1!$A$2:$A$16,Sheet1!$C$2:$C$16) -> Laurent Aboulin | C8: 92.88 | D8: 254.76 | E8: =TRUE -> TRUE | F8: =IF(E8, $B$37 * MAX(0, (C8 - 2/3*$B$23) / (1/3*$B$23)), 0) -> 298.05009 | G8: =IF(E8, $B$38, $B$38 * (D8/$B$30)) -> 290.4949 | H8: =Day_7[[#This Row],[Speed Pt]]+Day_7[[#This Row],[Dist Pt]] -> 588.54499 | I8: 0
A9: IP3 | B9: =_xlfn.XLOOKUP(Day_7[[#This Row],[Glider]],Sheet1!$A$2:$A$16,Sheet1!$C$2:$C$16) -> Pierre de Broqueville | C9: 90.88 | D9: 251.62 | E9: =IF(Day_7[[#This Row],[Speed]]>0,TRUE,FALSE) -> TRUE | F9: =IF(E9, $B$37 * MAX(0, (C9 - 2/3*$B$23) / (1/3*$B$23)), 0) -> 274.9514 | G9: =IF(E9, $B$38, $B$38 * (D9/$B$30)) -> 290.4949 | H9: =Day_7[[#This Row],[Speed Pt]]+Day_7[[#This Row],[Dist Pt]] -> 565.4463 | I9: 0
A10: UFO | B10: =_xlfn.XLOOKUP(Day_7[[#This Row],[Glider]],Sheet1!$A$2:$A$16,Sheet1!$C$2:$C$16) -> Max Leenders | C10: 90.29 | D10: 250.3 | E10: =IF(Day_7[[#This Row],[Speed]]>0,TRUE,FALSE) -> TRUE | F10: =IF(E10, $B$37 * MAX(0, (C10 - 2/3*$B$23) / (1/3*$B$23)), 0) -> 268.13729 | G10: =IF(E10, $B$38, $B$38 * (D10/$B$30)) -> 290.4949 | H10: =Day_7[[#This Row],[Speed Pt]]+Day_7[[#This Row],[Dist Pt]] -> 558.63219 | I10: 0
A11: EX | B11: =_xlfn.XLOOKUP(Day_7[[#This Row],[Glider]],Sheet1!$A$2:$A$16,Sheet1!$C$2:$C$16) -> Tomas Rendla | C11: 90.2 | D11: 255.3 | E11: =IF(Day_7[[#This Row],[Speed]]>0,TRUE,FALSE) -> TRUE | F11: =IF(E11, $B$37 * MAX(0, (C11 - 2/3*$B$23) / (1/3*$B$23)), 0) -> 267.09785 | G11: =IF(E11, $B$38, $B$38 * (D11/$B$30)) -> 290.4949 | H11: =Day_7[[#This Row],[Speed Pt]]+Day_7[[#This Row],[Dist Pt]] -> 557.59275 | I11: 0
A12: ZFI | B12: =_xlfn.XLOOKUP(Day_7[[#This Row],[Glider]],Sheet1!$A$2:$A$16,Sheet1!$C$2:$C$16) -> Jiri Kusbach | C12: 88.79 | D12: 248.89 | E12: =IF(Day_7[[#This Row],[Speed]]>0,TRUE,FALSE) -> TRUE | F12: =IF(E12, $B$37 * MAX(0, (C12 - 2/3*$B$23) / (1/3*$B$23)), 0) -> 250.81327 | G12: =IF(E12, $B$38, $B$38 * (D12/$B$30)) -> 290.4949 | H12: =Day_7[[#This Row],[Speed Pt]]+Day_7[[#This Row],[Dist Pt]]-Day_7[[#This Row],[Penalty]] -> 531.30817 | I12: 10
A13: 4D | B13: =_xlfn.XLOOKUP(Day_7[[#This Row],[Glider]],Sheet1!$A$2:$A$16,Sheet1!$C$2:$C$16) -> David Jansen | C13: 84.75 | D13: 248.87 | E13: =IF(Day_7[[#This Row],[Speed]]>0,TRUE,FALSE) -> TRUE | F13: =IF(E13, $B$37 * MAX(0, (C13 - 2/3*$B$23) / (1/3*$B$23)), 0) -> 204.15392 | G13: =IF(E13, $B$38, $B$38 * (D13/$B$30)) -> 290.4949 | H13: =Day_7[[#This Row],[Speed Pt]]+Day_7[[#This Row],[Dist Pt]] -> 494.64882 | I13: 0
A14: 1E | B14: =_xlfn.XLOOKUP(Day_7[[#This Row],[Glider]],Sheet1!$A$2:$A$16,Sheet1!$C$2:$C$16) -> Russell Cheetham | D14: 147.86 | E14: =IF(Day_7[[#This Row],[Speed]]>0,TRUE,FALSE) -> FALSE | F14: =IF(E14, $B$37 * MAX(0, (C14 - 2/3*$B$23) / (1/3*$B$23)), 0) -> 0 | G14: =IF(E14, $B$38, $B$38 * (D14/$B$30)) -> 165.33575 | H14: =Day_7[[#This Row],[Speed Pt]]+Day_7[[#This Row],[Dist Pt]] -> 165.33575 | I14: 0
A15: OG | B15: =_xlfn.XLOOKUP(Day_7[[#This Row],[Glider]],Sheet1!$A$2:$A$16,Sheet1!$C$2:$C$16) -> Oscar Goudriaan | D15: 69.94 | E15: =IF(Day_7[[#This Row],[Speed]]>0,TRUE,FALSE) -> FALSE | F15: =IF(E15, $B$37 * MAX(0, (C15 - 2/3*$B$23) / (1/3*$B$23)), 0) -> 0 | G15: =IF(E15, $B$38, $B$38 * (D15/$B$30)) -> 78.206294 | H15: =Day_7[[#This Row],[Speed Pt]]+Day_7[[#This Row],[Dist Pt]] -> 78.206294
A21: DM | B21: 140
A22: D1 | B22: 350
A23: V0 | B23: =MAX(C2:C15) -> 100.61
A24: T0 | B24: =D2/C2*3600 -> 9295.736
A26: N | B26: =COUNT(D2:D15) -> 14
A27: N1 | B27: =COUNTIF(D2:D15, ">=" & 140) -> 13
A28: N3 | B28: =COUNTIF(E2:E15, TRUE) -> 12
A29: N2 | B29: =COUNTIFS(E2:E15, TRUE, C2:C15, ">" & 2/3*$B$23) -> 12
A30: D0 | B30: =MAX(D2:D15) -> 259.79
A32: PmaxDist | B32: =1250 * (B30/B22) - 250 -> 677.82143
A33: PmaxTime | B33: =IF(B24<=0, 1000, (400*B24/3600) - 200) -> 832.85956
A34: Pm | B34: =MIN(B32,B33,1000) -> 677.82143
A35: F | B35: =MIN(1.25 * B27/B26, 1) -> 1
A36: Fcr | B36: =IF(B27>0, MIN(1.2*(B29/B27)+0.6, 1), 1) -> 1
A37: Pvm | B37: =(2/3) * (B29/B26) * B34 -> 387.32653
A38: Pdm | B38: =B34-B37 -> 290.4949

Sheet T8
A1: Glider | B1: Pilot | C1: Speed | D1: Distance | E1: Finished | F1: Speed Pt | G1: Dist Pt | H1: TOTAL PT | I1: Penalty
A2: 4D | B2: =_xlfn.XLOOKUP(Day_8[[#This Row],[Glider]],Sheet1!$A$2:$A$16,Sheet1!$C$2:$C$16) -> David Jansen | C2: 118.25 | D2: 420.04 | E2: =TRUE -> TRUE | F2: =IF(E2, $B$37 * MAX(0, (C2 - 2/3*$B$23) / (1/3*$B$23)), 0) -> 666.66667 | G2: =IF(E2, $B$38, $B$38 * (D2/$B$30)) -> 333.33333 | H2: =Day_8[[#This Row],[Speed Pt]]+Day_8[[#This Row],[Dist Pt]] -> 1000 | I2: 0
A3: YY | B3: =_xlfn.XLOOKUP(Day_8[[#This Row],[Glider]],Sheet1!$A$2:$A$16,Sheet1!$C$2:$C$16) -> Sebastian Kawa | C3: 116.94 | D3: 415.91 | E3: =TRUE -> TRUE | F3: =IF(E3, $B$37 * MAX(0, (C3 - 2/3*$B$23) / (1/3*$B$23)), 0) -> 644.51022 | G3: =IF(E3, $B$38, $B$38 * (D3/$B$30)) -> 333.33333 | H3: =Day_8[[#This Row],[Speed Pt]]+Day_8[[#This Row],[Dist Pt]] -> 977.84355 | I3: 0
A4: 1E | B4: =_xlfn.XLOOKUP(Day_8[[#This Row],[Glider]],Sheet1!$A$2:$A$16,Sheet1!$C$2:$C$16) -> Russell Cheetham | C4: 116.7 | D4: 412.62 | E4: =TRUE -> TRUE | F4: =IF(E4, $B$37 * MAX(0, (C4 - 2/3*$B$23) / (1/3*$B$23)), 0) -> 640.45102 | G4: =IF(E4, $B$38, $B$38 * (D4/$B$30)) -> 333.33333 | H4: =Day_8[[#This Row],[Speed Pt]]+Day_8[[#This Row],[Dist Pt]] -> 973.78436 | I4: 0
A5: 5 | B5: =_xlfn.XLOOKUP(Day_8[[#This Row],[Glider]],Sheet1!$A$2:$A$16,Sheet1!$C$2:$C$16) -> Laurent Aboulin | C5: 114.17 | D5: 409.85 | E5: =TRUE -> TRUE | F5: =IF(E5, $B$37 * MAX(0, (C5 - 2/3*$B$23) / (1/3*$B$23)), 0) -> 597.66032 | G5: =IF(E5, $B$38, $B$38 * (D5/$B$30)) -> 333.33333 | H5: =Day_8[[#This Row],[Speed Pt]]+Day_8[[#This Row],[Dist Pt]] -> 930.99366 | I5: 0
A6: FL | B6: =_xlfn.XLOOKUP(Day_8[[#This Row],[Glider]],Sheet1!$A$2:$A$16,Sheet1!$C$2:$C$16) -> Felipe Levin | C6: 113.42 | D6: 399.68 | E6: =TRUE -> TRUE | F6: =IF(E6, $B$37 * MAX(0, (C6 - 2/3*$B$23) / (1/3*$B$23)), 0) -> 584.97533 | G6: =IF(E6, $B$38, $B$38 * (D6/$B$30)) -> 333.33333 | H6: =Day_8[[#This Row],[Speed Pt]]+Day_8[[#This Row],[Dist Pt]] -> 918.30867 | I6: 0
A7: OR | B7: =_xlfn.XLOOKUP(Day_8[[#This Row],[Glider]],Sheet1!$A$2:$A$16,Sheet1!$C$2:$C$16) -> Michael Sommer | C7: 113.19 | D7: 399.58 | E7: =TRUE -> TRUE | F7: =IF(E7, $B$37 * MAX(0, (C7 - 2/3*$B$23) / (1/3*$B$23)), 0) -> 581.08527 | G7: =IF(E7, $B$38, $B$38 * (D7/$B$30)) -> 333.33333 | H7: =Day_8[[#This Row],[Speed Pt]]+Day_8[[#This Row],[Dist Pt]] -> 914.4186 | I7: 0
A8: XR | B8: =_xlfn.XLOOKUP(Day_8[[#This Row],[Glider]],Sheet1!$A$2:$A$16,Sheet1!$C$2:$C$16) -> Bas Seijffert | C8: 110.76 | D8: 396.03 | E8: =TRUE -> TRUE | F8: =IF(E8, $B$37 * MAX(0, (C8 - 2/3*$B$23) / (1/3*$B$23)), 0) -> 539.98591 | G8: =IF(E8, $B$38, $B$38 * (D8/$B$30)) -> 333.33333 | H8: =Day_8[[#This Row],[Speed Pt]]+Day_8[[#This Row],[Dist Pt]] -> 873.31924 | I8: 0
A9: EX | B9: =_xlfn.XLOOKUP(Day_8[[#This Row],[Glider]],Sheet1!$A$2:$A$16,Sheet1!$C$2:$C$16) -> Tomas Rendla | C9: 110.7 | D9: 396.16 | E9: =IF(Day_8[[#This Row],[Speed]]>0,TRUE,FALSE) -> TRUE | F9: =IF(E9, $B$37 * MAX(0, (C9 - 2/3*$B$23) / (1/3*$B$23)), 0) -> 538.97111 | G9: =IF(E9, $B$38, $B$38 * (D9/$B$30)) -> 333.33333 | H9: =Day_8[[#This Row],[Speed Pt]]+Day_8[[#This Row],[Dist Pt]] -> 872.30444 | I9: 0
A10: 72 | B10: =_xlfn.XLOOKUP(Day_8[[#This Row],[Glider]],Sheet1!$A$2:$A$16,Sheet1!$C$2:$C$16) -> Sylvain Gerbaud | C10: 107.2 | D10: 381.02 | E10: =IF(Day_8[[#This Row],[Speed]]>0,TRUE,FALSE) -> TRUE | F10: =IF(E10, $B$37 * MAX(0, (C10 - 2/3*$B$23) / (1/3*$B$23)), 0) -> 479.77449 | G10: =IF(E10, $B$38, $B$38 * (D10/$B$30)) -> 333.33333 | H10: =Day_8[[#This Row],[Speed Pt]]+Day_8[[#This Row],[Dist Pt]] -> 813.10782 | I10: 0
A11: UFO | B11: =_xlfn.XLOOKUP(Day_8[[#This Row],[Glider]],Sheet1!$A$2:$A$16,Sheet1!$C$2:$C$16) -> Max Leenders | C11: 104.02 | D11: 370.82 | E11: =IF(Day_8[[#This Row],[Speed]]>0,TRUE,FALSE) -> TRUE | F11: =IF(E11, $B$37 * MAX(0, (C11 - 2/3*$B$23) / (1/3*$B$23)), 0) -> 425.99013 | G11: =IF(E11, $B$38, $B$38 * (D11/$B$30)) -> 333.33333 | H11: =Day_8[[#This Row],[Speed Pt]]+Day_8[[#This Row],[Dist Pt]] -> 759.32347 | I11: 0
A12: ZFI | B12: =_xlfn.XLOOKUP(Day_8[[#This Row],[Glider]],Sheet1!$A$2:$A$16,Sheet1!$C$2:$C$16) -> Jiri Kusbach | C12: 103.53 | D12: 377.3 | E12: =IF(Day_8[[#This Row],[Speed]]>0,TRUE,FALSE) -> TRUE | F12: =IF(E12, $B$37 * MAX(0, (C12 - 2/3*$B$23) / (1/3*$B$23)), 0) -> 417.70261 | G12: =IF(E12, $B$38, $B$38 * (D12/$B$30)) -> 333.33333 | H12: =Day_8[[#This Row],[Speed Pt]]+Day_8[[#This Row],[Dist Pt]] -> 751.03594 | I12: 0
A13: OG | B13: =_xlfn.XLOOKUP(Day_8[[#This Row],[Glider]],Sheet1!$A$2:$A$16,Sheet1!$C$2:$C$16) -> Oscar Goudriaan | C13: 99.19 | D13: 354.09 | E13: =IF(Day_8[[#This Row],[Speed]]>0,TRUE,FALSE) -> TRUE | F13: =IF(E13, $B$37 * MAX(0, (C13 - 2/3*$B$23) / (1/3*$B$23)), 0) -> 344.2988 | G13: =IF(E13, $B$38, $B$38 * (D13/$B$30)) -> 333.33333 | H13: =Day_8[[#This Row],[Speed Pt]]+Day_8[[#This Row],[Dist Pt]] -> 677.63214 | I13: 0
A14: IP3 | B14: =_xlfn.XLOOKUP(Day_8[[#This Row],[Glider]],Sheet1!$A$2:$A$16,Sheet1!$C$2:$C$16) -> Pierre de Broqueville | C14: 95.94 | D14: 358.75 | E14: =IF(Day_8[[#This Row],[Speed]]>0,TRUE,FALSE) -> TRUE | F14: =IF(E14, $B$37 * MAX(0, (C14 - 2/3*$B$23) / (1/3*$B$23)), 0) -> 289.33051 | G14: =IF(E14, $B$38, $B$38 * (D14/$B$30)) -> 333.33333 | H14: =Day_8[[#This Row],[Speed Pt]]+Day_8[[#This Row],[Dist Pt]] -> 622.66385 | I14: 0
A15: DD | B15: =_xlfn.XLOOKUP(Day_8[[#This Row],[Glider]],Sheet1!$A$2:$A$16,Sheet1!$C$2:$C$16) -> Christian Hynek | C15: 95.84 | D15: 339.05 | E15: =IF(Day_8[[#This Row],[Speed]]>0,TRUE,FALSE) -> TRUE | F15: =IF(E15, $B$37 * MAX(0, (C15 - 2/3*$B$23) / (1/3*$B$23)), 0) -> 287.63918 | G15: =IF(E15, $B$38, $B$38 * (D15/$B$30)) -> 333.33333 | H15: =Day_8[[#This Row],[Speed Pt]]+Day_8[[#This Row],[Dist Pt]] -> 620.97252
A21: DM | B21: 140
A22: D1 | B22: 350
A23: V0 | B23: =MAX(C2:C15) -> 118.25
A24: T0 | B24: =D2/C2*3600 -> 12787.687
A26: N | B26: =COUNT(D2:D15) -> 14
A27: N1 | B27: =COUNTIF(D2:D15, ">=" & 140) -> 14
A28: N3 | B28: =COUNTIF(E2:E15, TRUE) -> 14
A29: N2 | B29: =COUNTIFS(E2:E15, TRUE, C2:C15, ">" & 2/3*$B$23) -> 14
A30: D0 | B30: =MAX(D2:D15) -> 420.04
A32: PmaxDist | B32: =1250 * (B30/B22) - 250 -> 1250.1429
A33: PmaxTime | B33: =IF(B24<=0, 1000, (400*B24/3600) - 200) -> 1220.8541
A34: Pm | B34: =MIN(B32,B33,1000) -> 1000
A35: F | B35: =MIN(1.25 * B27/B26, 1) -> 1
A36: Fcr | B36: =IF(B27>0, MIN(1.2*(B29/B27)+0.6, 1), 1) -> 1
A37: Pvm | B37: =(2/3) * (B29/B26) * B34 -> 666.66667
A38: Pdm | B38: =B34-B37 -> 333.33333

Sheet T9
A1: Glider | B1: Pilot | C1: Speed | D1: Distance | E1: Finished | F1: Speed Pt | G1: Dist Pt | H1: TOTAL PT | I1: Penalty
A2: FL | B2: =_xlfn.XLOOKUP(Day_9[[#This Row],[Glider]],Sheet1!$A$2:$A$16,Sheet1!$C$2:$C$16) -> Felipe Levin | C2: 143.2 | D2: 848.08 | E2: =TRUE -> TRUE | F2: =IF(E2, $B$37 * MAX(0, (C2 - 2/3*$B$23) / (1/3*$B$23)), 0) -> 619.04762 | G2: =IF(E2, $B$38, $B$38 * (D2/$B$30)) -> 380.95238 | H2: =Day_9[[#This Row],[Speed Pt]]+Day_9[[#This Row],[Dist Pt]] -> 1000 | I2: 0
A3: YY | B3: =_xlfn.XLOOKUP(Day_9[[#This Row],[Glider]],Sheet1!$A$2:$A$16,Sheet1!$C$2:$C$16) -> Sebastian Kawa | C3: 139.4 | D3: 848.08 | E3: =TRUE -> TRUE | F3: =IF(E3, $B$37 * MAX(0, (C3 - 2/3*$B$23) / (1/3*$B$23)), 0) -> 569.7659 | G3: =IF(E3, $B$38, $B$38 * (D3/$B$30)) -> 380.95238 | H3: =Day_9[[#This Row],[Speed Pt]]+Day_9[[#This Row],[Dist Pt]] -> 950.71828 | I3: 0
A4: OR | B4: =_xlfn.XLOOKUP(Day_9[[#This Row],[Glider]],Sheet1!$A$2:$A$16,Sheet1!$C$2:$C$16) -> Michael Sommer | C4: 139.16 | D4: 848.08 | E4: =TRUE -> TRUE | F4: =IF(E4, $B$37 * MAX(0, (C4 - 2/3*$B$23) / (1/3*$B$23)), 0) -> 566.65337 | G4: =IF(E4, $B$38, $B$38 * (D4/$B$30)) -> 380.95238 | H4: =Day_9[[#This Row],[Speed Pt]]+Day_9[[#This Row],[Dist Pt]] -> 947.60575 | I4: 0
A5: 5 | B5: =_xlfn.XLOOKUP(Day_9[[#This Row],[Glider]],Sheet1!$A$2:$A$16,Sheet1!$C$2:$C$16) -> Laurent Aboulin | C5: 139.11 | D5: 848.08 | E5: =TRUE -> TRUE | F5: =IF(E5, $B$37 * MAX(0, (C5 - 2/3*$B$23) / (1/3*$B$23)), 0) -> 566.00492 | G5: =IF(E5, $B$38, $B$38 * (D5/$B$30)) -> 380.95238 | H5: =Day_9[[#This Row],[Speed Pt]]+Day_9[[#This Row],[Dist Pt]] -> 946.9573 | I5: 0
A6: 72 | B6: =_xlfn.XLOOKUP(Day_9[[#This Row],[Glider]],Sheet1!$A$2:$A$16,Sheet1!$C$2:$C$16) -> Sylvain Gerbaud | C6: 138.56 | D6: 848.08 | E6: =TRUE -> TRUE | F6: =IF(E6, $B$37 * MAX(0, (C6 - 2/3*$B$23) / (1/3*$B$23)), 0) -> 558.87204 | G6: =IF(E6, $B$38, $B$38 * (D6/$B$30)) -> 380.95238 | H6: =Day_9[[#This Row],[Speed Pt]]+Day_9[[#This Row],[Dist Pt]] -> 939.82442 | I6: 0
A7: 4D | B7: =_xlfn.XLOOKUP(Day_9[[#This Row],[Glider]],Sheet1!$A$2:$A$16,Sheet1!$C$2:$C$16) -> David Jansen | C7: 137.7 | D7: 848.08 | E7: =TRUE -> TRUE | F7: =IF(E7, $B$37 * MAX(0, (C7 - 2/3*$B$23) / (1/3*$B$23)), 0) -> 547.71881 | G7: =IF(E7, $B$38, $B$38 * (D7/$B$30)) -> 380.95238 | H7: =Day_9[[#This Row],[Speed Pt]]+Day_9[[#This Row],[Dist Pt]] -> 928.67119 | I7: 0
A8: UFO | B8: =_xlfn.XLOOKUP(Day_9[[#This Row],[Glider]],Sheet1!$A$2:$A$16,Sheet1!$C$2:$C$16) -> Max Leenders | C8: 134.13 | D8: 848.08 | E8: =TRUE -> TRUE | F8: =IF(E8, $B$37 * MAX(0, (C8 - 2/3*$B$23) / (1/3*$B$23)), 0) -> 501.41993 | G8: =IF(E8, $B$38, $B$38 * (D8/$B$30)) -> 380.95238 | H8: =Day_9[[#This Row],[Speed Pt]]+Day_9[[#This Row],[Dist Pt]] -> 882.37231 | I8: 0
A9: XR | B9: =_xlfn.XLOOKUP(Day_9[[#This Row],[Glider]],Sheet1!$A$2:$A$16,Sheet1!$C$2:$C$16) -> Bas Seijffert | C9: 134.1 | D9: 848.08 | E9: =IF(Day_9[[#This Row],[Speed]]>0,TRUE,FALSE) -> TRUE | F9: =IF(E9, $B$37 * MAX(0, (C9 - 2/3*$B$23) / (1/3*$B$23)), 0) -> 501.03086 | G9: =IF(E9, $B$38, $B$38 * (D9/$B$30)) -> 380.95238 | H9: =Day_9[[#This Row],[Speed Pt]]+Day_9[[#This Row],[Dist Pt]] -> 881.98324 | I9: 0
A10: OG | B10: =_xlfn.XLOOKUP(Day_9[[#This Row],[Glider]],Sheet1!$A$2:$A$16,Sheet1!$C$2:$C$16) -> Oscar Goudriaan | C10: 133.3 | D10: 848.08 | E10: =IF(Day_9[[#This Row],[Speed]]>0,TRUE,FALSE) -> TRUE | F10: =IF(E10, $B$37 * MAX(0, (C10 - 2/3*$B$23) / (1/3*$B$23)), 0) -> 490.65576 | G10: =IF(E10, $B$38, $B$38 * (D10/$B$30)) -> 380.95238 | H10: =Day_9[[#This Row],[Speed Pt]]+Day_9[[#This Row],[Dist Pt]] -> 871.60814 | I10: 0
A11: IP3 | B11: =_xlfn.XLOOKUP(Day_9[[#This Row],[Glider]],Sheet1!$A$2:$A$16,Sheet1!$C$2:$C$16) -> Pierre de Broqueville | C11: 133.07 | D11: 848.08 | E11: =IF(Day_9[[#This Row],[Speed]]>0,TRUE,FALSE) -> TRUE | F11: =IF(E11, $B$37 * MAX(0, (C11 - 2/3*$B$23) / (1/3*$B$23)), 0) -> 487.67292 | G11: =IF(E11, $B$38, $B$38 * (D11/$B$30)) -> 380.95238 | H11: =Day_9[[#This Row],[Speed Pt]]+Day_9[[#This Row],[Dist Pt]] -> 868.6253 | I11: 0
A12: 1E | B12: =_xlfn.XLOOKUP(Day_9[[#This Row],[Glider]],Sheet1!$A$2:$A$16,Sheet1!$C$2:$C$16) -> Russell Cheetham | C12: 132.41 | D12: 848.08 | E12: =IF(Day_9[[#This Row],[Speed]]>0,TRUE,FALSE) -> TRUE | F12: =IF(E12, $B$37 * MAX(0, (C12 - 2/3*$B$23) / (1/3*$B$23)), 0) -> 479.11346 | G12: =IF(E12, $B$38, $B$38 * (D12/$B$30)) -> 380.95238 | H12: =Day_9[[#This Row],[Speed Pt]]+Day_9[[#This Row],[Dist Pt]] -> 860.06584 | I12: 0
A13: EX | B13: =_xlfn.XLOOKUP(Day_9[[#This Row],[Glider]],Sheet1!$A$2:$A$16,Sheet1!$C$2:$C$16) -> Tomas Rendla | C13: 132.11 | D13: 848.08 | E13: =IF(Day_9[[#This Row],[Speed]]>0,TRUE,FALSE) -> TRUE | F13: =IF(E13, $B$37 * MAX(0, (C13 - 2/3*$B$23) / (1/3*$B$23)), 0) -> 475.2228 | G13: =IF(E13, $B$38, $B$38 * (D13/$B$30)) -> 380.95238 | H13: =Day_9[[#This Row],[Speed Pt]]+Day_9[[#This Row],[Dist Pt]] -> 856.17518 | I13: 0
A14: ZFI | B14: =_xlfn.XLOOKUP(Day_9[[#This Row],[Glider]],Sheet1!$A$2:$A$16,Sheet1!$C$2:$C$16) -> Jiri Kusbach | C14: 128.39 | D14: 848.08 | E14: =IF(Day_9[[#This Row],[Speed]]>0,TRUE,FALSE) -> TRUE | F14: =IF(E14, $B$37 * MAX(0, (C14 - 2/3*$B$23) / (1/3*$B$23)), 0) -> 426.97858 | G14: =IF(E14, $B$38, $B$38 * (D14/$B$30)) -> 380.95238 | H14: =Day_9[[#This Row],[Speed Pt]]+Day_9[[#This Row],[Dist Pt]] -> 807.93097 | I14: 0
A15: DD | B15: =_xlfn.XLOOKUP(Day_9[[#This Row],[Glider]],Sheet1!$A$2:$A$16,Sheet1!$C$2:$C$16) -> Christian Hynek | D15: 778.08 | E15: =IF(Day_9[[#This Row],[Speed]]>0,TRUE,FALSE) -> FALSE | F15: =IF(E15, $B$37 * MAX(0, (C15 - 2/3*$B$23) / (1/3*$B$23)), 0) -> 0 | G15: =IF(E15, $B$38, $B$38 * (D15/$B$30)) -> 349.50881 | H15: =Day_9[[#This Row],[Speed Pt]]+Day_9[[#This Row],[Dist Pt]] -> 349.50881
A21: DM | B21: 140
A22: D1 | B22: 350
A23: V0 | B23: =MAX(C2:C15) -> 143.2
A24: T0 | B24: =D2/C2*3600 -> 21320.447
A26: N | B26: =COUNT(D2:D15) -> 14
A27: N1 | B27: =COUNTIF(D2:D15, ">=" & 140) -> 14
A28: N3 | B28: =COUNTIF(E2:E15, TRUE) -> 13
A29: N2 | B29: =COUNTIFS(E2:E15, TRUE, C2:C15, ">" & 2/3*$B$23) -> 13
A30: D0 | B30: =MAX(D2:D15) -> 848.08
A32: PmaxDist | B32: =1250 * (B30/B22) - 250 -> 2778.8571
A33: PmaxTime | B33: =IF(B24<=0, 1000, (400*B24/3600) - 200) -> 2168.9385
A34: Pm | B34: =MIN(B32,B33,1000) -> 1000
A35: F | B35: =MIN(1.25 * B27/B26, 1) -> 1
A36: Fcr | B36: =IF(B27>0, MIN(1.2*(B29/B27)+0.6, 1), 1) -> 1
A37: Pvm | B37: =(2/3) * (B29/B26) * B34 -> 619.04762
A38: Pdm | B38: =B34-B37 -> 380.95238

Sheet T10
A1: Glider | B1: Pilot | C1: Speed | D1: Distance | E1: Finished | F1: Speed Pt | G1: Dist Pt | H1: TOTAL PT | I1: Penalty
A2: YY | B2: =_xlfn.XLOOKUP(Day_10[[#This Row],[Glider]],Sheet1!$A$2:$A$16,Sheet1!$C$2:$C$16) -> Sebastian Kawa | C2: 135.19 | D2: 432.12 | E2: =TRUE -> TRUE | F2: =IF(E2, $B$37 * MAX(0, (C2 - 2/3*$B$23) / (1/3*$B$23)), 0) -> 571.42857 | G2: =IF(E2, $B$38, $B$38 * (D2/$B$30)) -> 428.57143 | H2: =Day_10[[#This Row],[Speed Pt]]+Day_10[[#This Row],[Dist Pt]] -> 1000 | I2: 0
A3: OR | B3: =_xlfn.XLOOKUP(Day_10[[#This Row],[Glider]],Sheet1!$A$2:$A$16,Sheet1!$C$2:$C$16) -> Michael Sommer | C3: 123.62 | D3: 389.03 | E3: =TRUE -> TRUE | F3: =IF(E3, $B$37 * MAX(0, (C3 - 2/3*$B$23) / (1/3*$B$23)), 0) -> 424.71442 | G3: =IF(E3, $B$38, $B$38 * (D3/$B$30)) -> 428.57143 | H3: =Day_10[[#This Row],[Speed Pt]]+Day_10[[#This Row],[Dist Pt]] -> 853.28585 | I3: 0
A4: FL | B4: =_xlfn.XLOOKUP(Day_10[[#This Row],[Glider]],Sheet1!$A$2:$A$16,Sheet1!$C$2:$C$16) -> Felipe Levin | C4: 123.45 | D4: 389.02 | E4: =TRUE -> TRUE | F4: =IF(E4, $B$37 * MAX(0, (C4 - 2/3*$B$23) / (1/3*$B$23)), 0) -> 422.55873 | G4: =IF(E4, $B$38, $B$38 * (D4/$B$30)) -> 428.57143 | H4: =Day_10[[#This Row],[Speed Pt]]+Day_10[[#This Row],[Dist Pt]] -> 851.13016 | I4: 0
A5: EX | B5: =_xlfn.XLOOKUP(Day_10[[#This Row],[Glider]],Sheet1!$A$2:$A$16,Sheet1!$C$2:$C$16) -> Tomas Rendla | C5: 117.07 | D5: 392.6 | E5: =TRUE -> TRUE | F5: =IF(E5, $B$37 * MAX(0, (C5 - 2/3*$B$23) / (1/3*$B$23)), 0) -> 341.65672 | G5: =IF(E5, $B$38, $B$38 * (D5/$B$30)) -> 428.57143 | H5: =Day_10[[#This Row],[Speed Pt]]+Day_10[[#This Row],[Dist Pt]] -> 770.22814 | I5: 0
A6: 5 | B6: =_xlfn.XLOOKUP(Day_10[[#This Row],[Glider]],Sheet1!$A$2:$A$16,Sheet1!$C$2:$C$16) -> Laurent Aboulin | C6: 116.9 | D6: 403.08 | E6: =TRUE -> TRUE | F6: =IF(E6, $B$37 * MAX(0, (C6 - 2/3*$B$23) / (1/3*$B$23)), 0) -> 339.50102 | G6: =IF(E6, $B$38, $B$38 * (D6/$B$30)) -> 428.57143 | H6: =Day_10[[#This Row],[Speed Pt]]+Day_10[[#This Row],[Dist Pt]] -> 768.07245 | I6: 0
A7: 72 | B7: =_xlfn.XLOOKUP(Day_10[[#This Row],[Glider]],Sheet1!$A$2:$A$16,Sheet1!$C$2:$C$16) -> Sylvain Gerbaud | C7: 116.89 | D7: 403.86 | E7: =TRUE -> TRUE | F7: =IF(E7, $B$37 * MAX(0, (C7 - 2/3*$B$23) / (1/3*$B$23)), 0) -> 339.37421 | G7: =IF(E7, $B$38, $B$38 * (D7/$B$30)) -> 428.57143 | H7: =Day_10[[#This Row],[Speed Pt]]+Day_10[[#This Row],[Dist Pt]] -> 767.94564 | I7: 0
A8: 1E | B8: =_xlfn.XLOOKUP(Day_10[[#This Row],[Glider]],Sheet1!$A$2:$A$16,Sheet1!$C$2:$C$16) -> Russell Cheetham | C8: 109.23 | D8: 410.7 | E8: =TRUE -> TRUE | F8: =IF(E8, $B$37 * MAX(0, (C8 - 2/3*$B$23) / (1/3*$B$23)), 0) -> 242.24108 | G8: =IF(E8, $B$38, $B$38 * (D8/$B$30)) -> 428.57143 | H8: =Day_10[[#This Row],[Speed Pt]]+Day_10[[#This Row],[Dist Pt]] -> 670.81251 | I8: 0
A9: IP3 | B9: =_xlfn.XLOOKUP(Day_10[[#This Row],[Glider]],Sheet1!$A$2:$A$16,Sheet1!$C$2:$C$16) -> Pierre de Broqueville | C9: 108.04 | D9: 405.98 | E9: =IF(Day_10[[#This Row],[Speed]]>0,TRUE,FALSE) -> TRUE | F9: =IF(E9, $B$37 * MAX(0, (C9 - 2/3*$B$23) / (1/3*$B$23)), 0) -> 227.15121 | G9: =IF(E9, $B$38, $B$38 * (D9/$B$30)) -> 428.57143 | H9: =Day_10[[#This Row],[Speed Pt]]+Day_10[[#This Row],[Dist Pt]] -> 655.72263 | I9: 0
